Workbook

Sheet Base Alan
A1: ID | B1: Data | C1: Faz | D1: Trat | E1: Bloco | F1: Rep | G1: Parcela | H1: Peso | I1: Média Peso | J1: Altura | K1: Altura média | L1: E.N | M1: E.N Médio | N1: PH | O1: Brix | P1: Pol | Q1: Pureza | R1: AR | S1: PC | T1: Ar_Atr | U1: Fibra | V1: Agio | W1: ATR | X1: TCH1 | Y1: TAH1 | Z1: TCH2 | AA1: TAH2 | AB1: TCH3 | AC1: TAH3 | AD1: TCH4 | AE1: TAH4 | AF1: TCH5 | AG1: TAH5 | AH1: TCH6 | AI1: TAH6 | AJ1: A | AK1: gs | AL1: Ci | AM1: E | AN1: EUA | AO1: EC | AP1: ETR | AQ1: Fv'/Fm' | AR1: PhiPS2 | AS1: qP | AT1: qN | AU1: VpdL | AV1: T° foliar | AW1: SPS | AX1: SuSy | AY1: SAI | AZ1: NI
A2: =B2&C2&D2&E2&F2&G2 -> 45733491B1R15 | B2: 45733 | C2: 49 | D2: 1 | E2: B1 | F2: R1 | G2: 5 | H2: =SUMIFS(Biometria!H:H,Biometria!$A:$A,$A2) -> 16 | I2: =SUMIFS(Biometria!I:I,Biometria!$A:$A,$A2) -> 17.67 | J2: =SUMIFS(Biometria!J:J,Biometria!$A:$A,$A2) -> 0 | K2: =SUMIFS(Biometria!K:K,Biometria!$A:$A,$A2) -> 2.95 | L2: =SUMIFS(Biometria!L:L,Biometria!$A:$A,$A2) -> 0 | M2: =SUMIFS(Biometria!M:M,Biometria!$A:$A,$A2) -> 0 | N2: =SUMIFS('A.T D0'!O:O,'A.T D0'!$A:$A,$A2)+SUMIFS('A.T D7'!O:O,'A.T D7'!$A:$A,$A2)+SUMIFS('A.T D22'!O:O,'A.T D22'!$A:$A,$A2)+SUMIFS('A.T D37'!O:O,'A.T D37'!$A:$A,$A2)+SUMIFS('A.T D52'!O:O,'A.T D52'!$A:$A,$A2)+SUMIFS('A.T D67'!O:O,'A.T D67'!$A:$A,$A2) -> 5.2 | O2: =SUMIFS('A.T D0'!P:P,'A.T D0'!$A:$A,$A2)+SUMIFS('A.T D7'!P:P,'A.T D7'!$A:$A,$A2)+SUMIFS('A.T D22'!P:P,'A.T D22'!$A:$A,$A2)+SUMIFS('A.T D37'!P:P,'A.T D37'!$A:$A,$A2)+SUMIFS('A.T D52'!P:P,'A.T D52'!$A:$A,$A2)+SUMIFS('A.T D67'!P:P,'A.T D67'!$A:$A,$A2) -> 18.53 | P2: =SUMIFS('A.T D0'!Q:Q,'A.T D0'!$A:$A,$A2)+SUMIFS('A.T D7'!Q:Q,'A.T D7'!$A:$A,$A2)+SUMIFS('A.T D22'!Q:Q,'A.T D22'!$A:$A,$A2)+SUMIFS('A.T D37'!Q:Q,'A.T D37'!$A:$A,$A2)+SUMIFS('A.T D52'!Q:Q,'A.T D52'!$A:$A,$A2)+SUMIFS('A.T D67'!Q:Q,'A.T D67'!$A:$A,$A2) -> 13.68 | Q2: =SUMIFS('A.T D0'!R:R,'A.T D0'!$A:$A,$A2)+SUMIFS('A.T D7'!R:R,'A.T D7'!$A:$A,$A2)+SUMIFS('A.T D22'!R:R,'A.T D22'!$A:$A,$A2)+SUMIFS('A.T D37'!R:R,'A.T D37'!$A:$A,$A2)+SUMIFS('A.T D52'!R:R,'A.T D52'!$A:$A,$A2)+SUMIFS('A.T D67'!R:R,'A.T D67'!$A:$A,$A2) -> 73.83 | R2: =SUMIFS('A.T D0'!S:S,'A.T D0'!$A:$A,$A2)+SUMIFS('A.T D7'!S:S,'A.T D7'!$A:$A,$A2)+SUMIFS('A.T D22'!S:S,'A.T D22'!$A:$A,$A2)+SUMIFS('A.T D37'!S:S,'A.T D37'!$A:$A,$A2)+SUMIFS('A.T D52'!S:S,'A.T D52'!$A:$A,$A2)+SUMIFS('A.T D67'!S:S,'A.T D67'!$A:$A,$A2) -> 1.11 | S2: =SUMIFS('A.T D0'!T:T,'A.T D0'!$A:$A,$A2)+SUMIFS('A.T D7'!T:T,'A.T D7'!$A:$A,$A2)+SUMIFS('A.T D22'!T:T,'A.T D22'!$A:$A,$A2)+SUMIFS('A.T D37'!T:T,'A.T D37'!$A:$A,$A2)+SUMIFS('A.T D52'!T:T,'A.T D52'!$A:$A,$A2)+SUMIFS('A.T D67'!T:T,'A.T D67'!$A:$A,$A2) -> 11.4743 | T2: =SUMIFS('A.T D0'!U:U,'A.T D0'!$A:$A,$A2)+SUMIFS('A.T D7'!U:U,'A.T D7'!$A:$A,$A2)+SUMIFS('A.T D22'!U:U,'A.T D22'!$A:$A,$A2)+SUMIFS('A.T D37'!U:U,'A.T D37'!$A:$A,$A2)+SUMIFS('A.T D52'!U:U,'A.T D52'!$A:$A,$A2)+SUMIFS('A.T D67'!U:U,'A.T D67'!$A:$A,$A2) -> 0.93 | U2: =SUMIFS('A.T D0'!V:V,'A.T D0'!$A:$A,$A2)+SUMIFS('A.T D7'!V:V,'A.T D7'!$A:$A,$A2)+SUMIFS('A.T D22'!V:V,'A.T D22'!$A:$A,$A2)+SUMIFS('A.T D37'!V:V,'A.T D37'!$A:$A,$A2)+SUMIFS('A.T D52'!V:V,'A.T D52'!$A:$A,$A2)+SUMIFS('A.T D67'!V:V,'A.T D67'!$A:$A,$A2) -> 12.55 | V2: =SUMIFS('A.T D0'!W:W,'A.T D0'!$A:$A,$A2)+SUMIFS('A.T D7'!W:W,'A.T D7'!$A:$A,$A2)+SUMIFS('A.T D22'!W:W,'A.T D22'!$A:$A,$A2)+SUMIFS('A.T D37'!W:W,'A.T D37'!$A:$A,$A2)+SUMIFS('A.T D52'!W:W,'A.T D52'!$A:$A,$A2)+SUMIFS('A.T D67'!W:W,'A.T D67'!$A:$A,$A2) -> 0.38 | W2: =SUMIFS('A.T D0'!X:X,'A.T D0'!$A:$A,$A2)+SUMIFS('A.T D7'!X:X,'A.T D7'!$A:$A,$A2)+SUMIFS('A.T D22'!X:X,'A.T D22'!$A:$A,$A2)+SUMIFS('A.T D37'!X:X,'A.T D37'!$A:$A,$A2)+SUMIFS('A.T D52'!X:X,'A.T D52'!$A:$A,$A2)+SUMIFS('A.T D67'!X:X,'A.T D67'!$A:$A,$A2) -> 119.03 | X2: =SUMIFS(TCH!J:J,TCH!$A:$A,$A2) -> 0 | Y2: =IF(X2=0,0,(X2*AVERAGEIFS($W:$W,$C:$C,$C2,$D:$D,$D2,$E:$E,$E2,$G:$G,$G2,$B:$B,_xlfn.MAXIFS($B:$B,$C:$C,$C2,$D:$D,$D2,$E:$E,$E2,$G:$G,$G2,$B:$B,"<>"&$B2)))/1000) -> 0 | Z2: =SUMIFS(TCH!M:M,TCH!$A:$A,$A2) -> 0 | AA2: =IF(Z2=0,0,(Z2*AVERAGEIFS($W:$W,$C:$C,$C2,$D:$D,$D2,$E:$E,$E2,$G:$G,$G2,$B:$B,_xlfn.MAXIFS($B:$B,$C:$C,$C2,$D:$D,$D2,$E:$E,$E2,$G:$G,$G2,$B:$B,"<>"&$B2)))/1000) -> 0 | AB2: =SUMIFS(TCH!P:P,TCH!$A:$A,$A2) -> 0 | AC2: =IF(AB2=0,0,(AB2*AVERAGEIFS($W:$W,$C:$C,$C2,$D:$D,$D2,$E:$E,$E2,$G:$G,$G2,$B:$B,_xlfn.MAXIFS($B:$B,$C:$C,$C2,$D:$D,$D2,$E:$E,$E2,$G:$G,$G2,$B:$B,"<>"&$B2)))/1000) -> 0 | AD2: =SUMIFS(TCH!S:S,TCH!$A:$A,$A2) -> 0 | AE2: =IF(AD2=0,0,(AD2*AVERAGEIFS($W:$W,$C:$C,$C2,$D:$D,$D2,$E:$E,$E2,$G:$G,$G2,$B:$B,_xlfn.MAXIFS($B:$B,$C:$C,$C2,$D:$D,$D2,$E:$E,$E2,$G:$G,$G2,$B:$B,"<>"&$B2)))/1000) -> 0 | AF2: =SUMIFS(TCH!V:V,TCH!$A:$A,$A2) -> 0 | AG2: =IF(AF2=0,0,(AF2*AVERAGEIFS($W:$W,$C:$C,$C2,$D:$D,$D2,$E:$E,$E2,$G:$G,$G2,$B:$B,_xlfn.MAXIFS($B:$B,$C:$C,$C2,$D:$D,$D2,$E:$E,$E2,$G:$G,$G2,$B:$B,"<>"&$B2)))/1000) -> 0 | AH2: =SUMIFS(TCH!Y:Y,TCH!$A:$A,$A2) -> 0 | AI2: =IF(AH2=0,0,(AH2*AVERAGEIFS($W:$W,$C:$C,$C2,$D:$D,$D2,$E:$E,$E2,$G:$G,$G2,$B:$B,_xlfn.MAXIFS($B:$B,$C:$C,$C2,$D:$D,$D2,$E:$E,$E2,$G:$G,$G2,$B:$B,"<>"&$B2)))/1000) -> 0 | AJ2: 0 | AK2: 0 | AL2: 0 | AM2: 0 | AN2: 0 | AO2: 0 | AP2: 0 | AQ2: 0 | AR2: 0 | AS2: 0 | AT2: 0 | AU2: 0 | AV2: 0 | AW2: 0 | AX2: 0 | AY2: 0 | AZ2: 0
A3: =B3&C3&D3&E3&F3&G3 -> 45733491B1R25 | B3: 45733 | C3: 49 | D3: 1 | E3: B1 | F3: R2 | G3: 5 | H3: =SUMIFS(Biometria!H:H,Biometria!$A:$A,$A3) -> 19.54 | I3: =SUMIFS(Biometria!I:I,Biometria!$A:$A,$A3) -> 0 | J3: =SUMIFS(Biometria!J:J,Biometria!$A:$A,$A3) -> 0 | K3: =SUMIFS(Biometria!K:K,Biometria!$A:$A,$A3) -> 0 | L3: =SUMIFS(Biometria!L:L,Biometria!$A:$A,$A3) -> 0 | M3: =SUMIFS(Biometria!M:M,Biometria!$A:$A,$A3) -> 0 | N3: =SUMIFS('A.T D0'!O:O,'A.T D0'!$A:$A,$A3)+SUMIFS('A.T D7'!O:O,'A.T D7'!$A:$A,$A3)+SUMIFS('A.T D22'!O:O,'A.T D22'!$A:$A,$A3)+SUMIFS('A.T D37'!O:O,'A.T D37'!$A:$A,$A3)+SUMIFS('A.T D52'!O:O,'A.T D52'!$A:$A,$A3)+SUMIFS('A.T D67'!O:O,'A.T D67'!$A:$A,$A3) -> 5.2 | O3: =SUMIFS('A.T D0'!P:P,'A.T D0'!$A:$A,$A3)+SUMIFS('A.T D7'!P:P,'A.T D7'!$A:$A,$A3)+SUMIFS('A.T D22'!P:P,'A.T D22'!$A:$A,$A3)+SUMIFS('A.T D37'!P:P,'A.T D37'!$A:$A,$A3)+SUMIFS('A.T D52'!P:P,'A.T D52'!$A:$A,$A3)+SUMIFS('A.T D67'!P:P,'A.T D67'!$A:$A,$A3) -> 17.31 | P3: =SUMIFS('A.T D0'!Q:Q,'A.T D0'!$A:$A,$A3)+SUMIFS('A.T D7'!Q:Q,'A.T D7'!$A:$A,$A3)+SUMIFS('A.T D22'!Q:Q,'A.T D22'!$A:$A,$A3)+SUMIFS('A.T D37'!Q:Q,'A.T D37'!$A:$A,$A3)+SUMIFS('A.T D52'!Q:Q,'A.T D52'!$A:$A,$A3)+SUMIFS('A.T D67'!Q:Q,'A.T D67'!$A:$A,$A3) -> 13.29 | Q3: =SUMIFS('A.T D0'!R:R,'A.T D0'!$A:$A,$A3)+SUMIFS('A.T D7'!R:R,'A.T D7'!$A:$A,$A3)+SUMIFS('A.T D22'!R:R,'A.T D22'!$A:$A,$A3)+SUMIFS('A.T D37'!R:R,'A.T D37'!$A:$A,$A3)+SUMIFS('A.T D52'!R:R,'A.T D52'!$A:$A,$A3)+SUMIFS('A.T D67'!R:R,'A.T D67'!$A:$A,$A3) -> 76.78 | R3: =SUMIFS('A.T D0'!S:S,'A.T D0'!$A:$A,$A3)+SUMIFS('A.T D7'!S:S,'A.T D7'!$A:$A,$A3)+SUMIFS('A.T D22'!S:S,'A.T D22'!$A:$A,$A3)+SUMIFS('A.T D37'!S:S,'A.T D37'!$A:$A,$A3)+SUMIFS('A.T D52'!S:S,'A.T D52'!$A:$A,$A3)+SUMIFS('A.T D67'!S:S,'A.T D67'!$A:$A,$A3) -> 1.01 | S3: =SUMIFS('A.T D0'!T:T,'A.T D0'!$A:$A,$A3)+SUMIFS('A.T D7'!T:T,'A.T D7'!$A:$A,$A3)+SUMIFS('A.T D22'!T:T,'A.T D22'!$A:$A,$A3)+SUMIFS('A.T D37'!T:T,'A.T D37'!$A:$A,$A3)+SUMIFS('A.T D52'!T:T,'A.T D52'!$A:$A,$A3)+SUMIFS('A.T D67'!T:T,'A.T D67'!$A:$A,$A3) -> 11.1142 | T3: =SUMIFS('A.T D0'!U:U,'A.T D0'!$A:$A,$A3)+SUMIFS('A.T D7'!U:U,'A.T D7'!$A:$A,$A3)+SUMIFS('A.T D22'!U:U,'A.T D22'!$A:$A,$A3)+SUMIFS('A.T D37'!U:U,'A.T D37'!$A:$A,$A3)+SUMIFS('A.T D52'!U:U,'A.T D52'!$A:$A,$A3)+SUMIFS('A.T D67'!U:U,'A.T D67'!$A:$A,$A3) -> 0.84 | U3: =SUMIFS('A.T D0'!V:V,'A.T D0'!$A:$A,$A3)+SUMIFS('A.T D7'!V:V,'A.T D7'!$A:$A,$A3)+SUMIFS('A.T D22'!V:V,'A.T D22'!$A:$A,$A3)+SUMIFS('A.T D37'!V:V,'A.T D37'!$A:$A,$A3)+SUMIFS('A.T D52'!V:V,'A.T D52'!$A:$A,$A3)+SUMIFS('A.T D67'!V:V,'A.T D67'!$A:$A,$A3) -> 12.72 | V3: =SUMIFS('A.T D0'!W:W,'A.T D0'!$A:$A,$A3)+SUMIFS('A.T D7'!W:W,'A.T D7'!$A:$A,$A3)+SUMIFS('A.T D22'!W:W,'A.T D22'!$A:$A,$A3)+SUMIFS('A.T D37'!W:W,'A.T D37'!$A:$A,$A3)+SUMIFS('A.T D52'!W:W,'A.T D52'!$A:$A,$A3)+SUMIFS('A.T D67'!W:W,'A.T D67'!$A:$A,$A3) -> -3.25 | W3: =SUMIFS('A.T D0'!X:X,'A.T D0'!$A:$A,$A3)+SUMIFS('A.T D7'!X:X,'A.T D7'!$A:$A,$A3)+SUMIFS('A.T D22'!X:X,'A.T D22'!$A:$A,$A3)+SUMIFS('A.T D37'!X:X,'A.T D37'!$A:$A,$A3)+SUMIFS('A.T D52'!X:X,'A.T D52'!$A:$A,$A3)+SUMIFS('A.T D67'!X:X,'A.T D67'!$A:$A,$A3) -> 114.73 | X3: =SUMIFS(TCH!J:J,TCH!$A:$A,$A3) -> 0 | Y3: =IF(X3=0,0,(X3*AVERAGEIFS($W:$W,$C:$C,$C3,$D:$D,$D3,$E:$E,$E3,$G:$G,$G3,$B:$B,_xlfn.MAXIFS($B:$B,$C:$C,$C3,$D:$D,$D3,$E:$E,$E3,$G:$G,$G3,$B:$B,"<>"&$B3)))/1000) -> 0 | Z3: =SUMIFS(TCH!M:M,TCH!$A:$A,$A3) -> 0 | AA3: =IF(Z3=0,0,(Z3*AVERAGEIFS($W:$W,$C:$C,$C3,$D:$D,$D3,$E:$E,$E3,$G:$G,$G3,$B:$B,_xlfn.MAXIFS($B:$B,$C:$C,$C3,$D:$D,$D3,$E:$E,$E3,$G:$G,$G3,$B:$B,"<>"&$B3)))/1000) -> 0 | AB3: =SUMIFS(TCH!P:P,TCH!$A:$A,$A3) -> 0 | AC3: =IF(AB3=0,0,(AB3*AVERAGEIFS($W:$W,$C:$C,$C3,$D:$D,$D3,$E:$E,$E3,$G:$G,$G3,$B:$B,_xlfn.MAXIFS($B:$B,$C:$C,$C3,$D:$D,$D3,$E:$E,$E3,$G:$G,$G3,$B:$B,"<>"&$B3)))/1000) -> 0 | AD3: =SUMIFS(TCH!S:S,TCH!$A:$A,$A3) -> 0 | AE3: =IF(AD3=0,0,(AD3*AVERAGEIFS($W:$W,$C:$C,$C3,$D:$D,$D3,$E:$E,$E3,$G:$G,$G3,$B:$B,_xlfn.MAXIFS($B:$B,$C:$C,$C3,$D:$D,$D3,$E:$E,$E3,$G:$G,$G3,$B:$B,"<>"&$B3)))/1000) -> 0 | AF3: =SUMIFS(TCH!V:V,TCH!$A:$A,$A3) -> 0 | AG3: =IF(AF3=0,0,(AF3*AVERAGEIFS($W:$W,$C:$C,$C3,$D:$D,$D3,$E:$E,$E3,$G:$G,$G3,$B:$B,_xlfn.MAXIFS($B:$B,$C:$C,$C3,$D:$D,$D3,$E:$E,$E3,$G:$G,$G3,$B:$B,"<>"&$B3)))/1000) -> 0 | AH3: =SUMIFS(TCH!Y:Y,TCH!$A:$A,$A3) -> 0 | AI3: =IF(AH3=0,0,(AH3*AVERAGEIFS($W:$W,$C:$C,$C3,$D:$D,$D3,$E:$E,$E3,$G:$G,$G3,$B:$B,_xlfn.MAXIFS($B:$B,$C:$C,$C3,$D:$D,$D3,$E:$E,$E3,$G:$G,$G3,$B:$B,"<>"&$B3)))/1000) -> 0 | AJ3: 0 | AK3: 0 | AL3: 0 | AM3: 0 | AN3: 0 | AO3: 0 | AP3: 0 | AQ3: 0 | AR3: 0 | AS3: 0 | AT3: 0 | AU3: 0 | AV3: 0 | AW3: 0 | AX3: 0 | AY3: 0 | AZ3: 0
A4: =B4&C4&D4&E4&F4&G4 -> 45733491B1R35 | B4: 45733 | C4: 49 | D4: 1 | E4: B1 | F4: R3 | G4: 5 | H4: =SUMIFS(Biometria!H:H,Biometria!$A:$A,$A4) -> 17.47 | I4: =SUMIFS(Biometria!I:I,Biometria!$A:$A,$A4) -> 0 | J4: =SUMIFS(Biometria!J:J,Biometria!$A:$A,$A4) -> 0 | K4: =SUMIFS(Biometria!K:K,Biometria!$A:$A,$A4) -> 0 | L4: =SUMIFS(Biometria!L:L,Biometria!$A:$A,$A4) -> 0 | M4: =SUMIFS(Biometria!M:M,Biometria!$A:$A,$A4) -> 0 | N4: =SUMIFS('A.T D0'!O:O,'A.T D0'!$A:$A,$A4)+SUMIFS('A.T D7'!O:O,'A.T D7'!$A:$A,$A4)+SUMIFS('A.T D22'!O:O,'A.T D22'!$A:$A,$A4)+SUMIFS('A.T D37'!O:O,'A.T D37'!$A:$A,$A4)+SUMIFS('A.T D52'!O:O,'A.T D52'!$A:$A,$A4)+SUMIFS('A.T D67'!O:O,'A.T D67'!$A:$A,$A4) -> 5.2 | O4: =SUMIFS('A.T D0'!P:P,'A.T D0'!$A:$A,$A4)+SUMIFS('A.T D7'!P:P,'A.T D7'!$A:$A,$A4)+SUMIFS('A.T D22'!P:P,'A.T D22'!$A:$A,$A4)+SUMIFS('A.T D37'!P:P,'A.T D37'!$A:$A,$A4)+SUMIFS('A.T D52'!P:P,'A.T D52'!$A:$A,$A4)+SUMIFS('A.T D67'!P:P,'A.T D67'!$A:$A,$A4) -> 17.54 | P4: =SUMIFS('A.T D0'!Q:Q,'A.T D0'!$A:$A,$A4)+SUMIFS('A.T D7'!Q:Q,'A.T D7'!$A:$A,$A4)+SUMIFS('A.T D22'!Q:Q,'A.T D22'!$A:$A,$A4)+SUMIFS('A.T D37'!Q:Q,'A.T D37'!$A:$A,$A4)+SUMIFS('A.T D52'!Q:Q,'A.T D52'!$A:$A,$A4)+SUMIFS('A.T D67'!Q:Q,'A.T D67'!$A:$A,$A4) -> 12.77 | Q4: =SUMIFS('A.T D0'!R:R,'A.T D0'!$A:$A,$A4)+SUMIFS('A.T D7'!R:R,'A.T D7'!$A:$A,$A4)+SUMIFS('A.T D22'!R:R,'A.T D22'!$A:$A,$A4)+SUMIFS('A.T D37'!R:R,'A.T D37'!$A:$A,$A4)+SUMIFS('A.T D52'!R:R,'A.T D52'!$A:$A,$A4)+SUMIFS('A.T D67'!R:R,'A.T D67'!$A:$A,$A4) -> 72.81 | R4: =SUMIFS('A.T D0'!S:S,'A.T D0'!$A:$A,$A4)+SUMIFS('A.T D7'!S:S,'A.T D7'!$A:$A,$A4)+SUMIFS('A.T D22'!S:S,'A.T D22'!$A:$A,$A4)+SUMIFS('A.T D37'!S:S,'A.T D37'!$A:$A,$A4)+SUMIFS('A.T D52'!S:S,'A.T D52'!$A:$A,$A4)+SUMIFS('A.T D67'!S:S,'A.T D67'!$A:$A,$A4) -> 1.14 | S4: =SUMIFS('A.T D0'!T:T,'A.T D0'!$A:$A,$A4)+SUMIFS('A.T D7'!T:T,'A.T D7'!$A:$A,$A4)+SUMIFS('A.T D22'!T:T,'A.T D22'!$A:$A,$A4)+SUMIFS('A.T D37'!T:T,'A.T D37'!$A:$A,$A4)+SUMIFS('A.T D52'!T:T,'A.T D52'!$A:$A,$A4)+SUMIFS('A.T D67'!T:T,'A.T D67'!$A:$A,$A4) -> 10.7465 | T4: =SUMIFS('A.T D0'!U:U,'A.T D0'!$A:$A,$A4)+SUMIFS('A.T D7'!U:U,'A.T D7'!$A:$A,$A4)+SUMIFS('A.T D22'!U:U,'A.T D22'!$A:$A,$A4)+SUMIFS('A.T D37'!U:U,'A.T D37'!$A:$A,$A4)+SUMIFS('A.T D52'!U:U,'A.T D52'!$A:$A,$A4)+SUMIFS('A.T D67'!U:U,'A.T D67'!$A:$A,$A4) -> 0.96 | U4: =SUMIFS('A.T D0'!V:V,'A.T D0'!$A:$A,$A4)+SUMIFS('A.T D7'!V:V,'A.T D7'!$A:$A,$A4)+SUMIFS('A.T D22'!V:V,'A.T D22'!$A:$A,$A4)+SUMIFS('A.T D37'!V:V,'A.T D37'!$A:$A,$A4)+SUMIFS('A.T D52'!V:V,'A.T D52'!$A:$A,$A4)+SUMIFS('A.T D67'!V:V,'A.T D67'!$A:$A,$A4) -> 12.36 | V4: =SUMIFS('A.T D0'!W:W,'A.T D0'!$A:$A,$A4)+SUMIFS('A.T D7'!W:W,'A.T D7'!$A:$A,$A4)+SUMIFS('A.T D22'!W:W,'A.T D22'!$A:$A,$A4)+SUMIFS('A.T D37'!W:W,'A.T D37'!$A:$A,$A4)+SUMIFS('A.T D52'!W:W,'A.T D52'!$A:$A,$A4)+SUMIFS('A.T D67'!W:W,'A.T D67'!$A:$A,$A4) -> -5.3 | W4: =SUMIFS('A.T D0'!X:X,'A.T D0'!$A:$A,$A4)+SUMIFS('A.T D7'!X:X,'A.T D7'!$A:$A,$A4)+SUMIFS('A.T D22'!X:X,'A.T D22'!$A:$A,$A4)+SUMIFS('A.T D37'!X:X,'A.T D37'!$A:$A,$A4)+SUMIFS('A.T D52'!X:X,'A.T D52'!$A:$A,$A4)+SUMIFS('A.T D67'!X:X,'A.T D67'!$A:$A,$A4) -> 112.29 | X4: =SUMIFS(TCH!J:J,TCH!$A:$A,$A4) -> 0 | Y4: =IF(X4=0,0,(X4*AVERAGEIFS($W:$W,$C:$C,$C4,$D:$D,$D4,$E:$E,$E4,$G:$G,$G4,$B:$B,_xlfn.MAXIFS($B:$B,$C:$C,$C4,$D:$D,$D4,$E:$E,$E4,$G:$G,$G4,$B:$B,"<>"&$B4)))/1000) -> 0 | Z4: =SUMIFS(TCH!M:M,TCH!$A:$A,$A4) -> 0 | AA4: =IF(Z4=0,0,(Z4*AVERAGEIFS($W:$W,$C:$C,$C4,$D:$D,$D4,$E:$E,$E4,$G:$G,$G4,$B:$B,_xlfn.MAXIFS($B:$B,$C:$C,$C4,$D:$D,$D4,$E:$E,$E4,$G:$G,$G4,$B:$B,"<>"&$B4)))/1000) -> 0 | AB4: =SUMIFS(TCH!P:P,TCH!$A:$A,$A4) -> 0 | AC4: =IF(AB4=0,0,(AB4*AVERAGEIFS($W:$W,$C:$C,$C4,$D:$D,$D4,$E:$E,$E4,$G:$G,$G4,$B:$B,_xlfn.MAXIFS($B:$B,$C:$C,$C4,$D:$D,$D4,$E:$E,$E4,$G:$G,$G4,$B:$B,"<>"&$B4)))/1000) -> 0 | AD4: =SUMIFS(TCH!S:S,TCH!$A:$A,$A4) -> 0 | AE4: =IF(AD4=0,0,(AD4*AVERAGEIFS($W:$W,$C:$C,$C4,$D:$D,$D4,$E:$E,$E4,$G:$G,$G4,$B:$B,_xlfn.MAXIFS($B:$B,$C:$C,$C4,$D:$D,$D4,$E:$E,$E4,$G:$G,$G4,$B:$B,"<>"&$B4)))/1000) -> 0 | AF4: =SUMIFS(TCH!V:V,TCH!$A:$A,$A4) -> 0 | AG4: =IF(AF4=0,0,(AF4*AVERAGEIFS($W:$W,$C:$C,$C4,$D:$D,$D4,$E:$E,$E4,$G:$G,$G4,$B:$B,_xlfn.MAXIFS($B:$B,$C:$C,$C4,$D:$D,$D4,$E:$E,$E4,$G:$G,$G4,$B:$B,"<>"&$B4)))/1000) -> 0 | AH4: =SUMIFS(TCH!Y:Y,TCH!$A:$A,$A4) -> 0 | AI4: =IF(AH4=0,0,(AH4*AVERAGEIFS($W:$W,$C:$C,$C4,$D:$D,$D4,$E:$E,$E4,$G:$G,$G4,$B:$B,_xlfn.MAXIFS($B:$B,$C:$C,$C4,$D:$D,$D4,$E:$E,$E4,$G:$G,$G4,$B:$B,"<>"&$B4)))/1000) -> 0 | AJ4: 0 | AK4: 0 | AL4: 0 | AM4: 0 | AN4: 0 | AO4: 0 | AP4: 0 | AQ4: 0 | AR4: 0 | AS4: 0 | AT4: 0 | AU4: 0 | AV4: 0 | AW4: 0 | AX4: 0 | AY4: 0 | AZ4: 0
A5: =B5&C5&D5&E5&F5&G5 -> 45733491B3R19 | B5: 45733 | C5: 49 | D5: 1 | E5: B3 | F5: R1 | G5: 9 | H5: =SUMIFS(Biometria!H:H,Biometria!$A:$A,$A5) -> 12.8 | I5: =SUMIFS(Biometria!I:I,Biometria!$A:$A,$A5) -> 13.43 | J5: =SUMIFS(Biometria!J:J,Biometria!$A:$A,$A5) -> 0 | K5: =SUMIFS(Biometria!K:K,Biometria!$A:$A,$A5) -> 2.69 | L5: =SUMIFS(Biometria!L:L,Biometria!$A:$A,$A5) -> 0 | M5: =SUMIFS(Biometria!M:M,Biometria!$A:$A,$A5) -> 0 | N5: =SUMIFS('A.T D0'!O:O,'A.T D0'!$A:$A,$A5)+SUMIFS('A.T D7'!O:O,'A.T D7'!$A:$A,$A5)+SUMIFS('A.T D22'!O:O,'A.T D22'!$A:$A,$A5)+SUMIFS('A.T D37'!O:O,'A.T D37'!$A:$A,$A5)+SUMIFS('A.T D52'!O:O,'A.T D52'!$A:$A,$A5)+SUMIFS('A.T D67'!O:O,'A.T D67'!$A:$A,$A5) -> 5.2 | O5: =SUMIFS('A.T D0'!P:P,'A.T D0'!$A:$A,$A5)+SUMIFS('A.T D7'!P:P,'A.T D7'!$A:$A,$A5)+SUMIFS('A.T D22'!P:P,'A.T D22'!$A:$A,$A5)+SUMIFS('A.T D37'!P:P,'A.T D37'!$A:$A,$A5)+SUMIFS('A.T D52'!P:P,'A.T D52'!$A:$A,$A5)+SUMIFS('A.T D67'!P:P,'A.T D67'!$A:$A,$A5) -> 18.01 | P5: =SUMIFS('A.T D0'!Q:Q,'A.T D0'!$A:$A,$A5)+SUMIFS('A.T D7'!Q:Q,'A.T D7'!$A:$A,$A5)+SUMIFS('A.T D22'!Q:Q,'A.T D22'!$A:$A,$A5)+SUMIFS('A.T D37'!Q:Q,'A.T D37'!$A:$A,$A5)+SUMIFS('A.T D52'!Q:Q,'A.T D52'!$A:$A,$A5)+SUMIFS('A.T D67'!Q:Q,'A.T D67'!$A:$A,$A5) -> 13.49 | Q5: =SUMIFS('A.T D0'!R:R,'A.T D0'!$A:$A,$A5)+SUMIFS('A.T D7'!R:R,'A.T D7'!$A:$A,$A5)+SUMIFS('A.T D22'!R:R,'A.T D22'!$A:$A,$A5)+SUMIFS('A.T D37'!R:R,'A.T D37'!$A:$A,$A5)+SUMIFS('A.T D52'!R:R,'A.T D52'!$A:$A,$A5)+SUMIFS('A.T D67'!R:R,'A.T D67'!$A:$A,$A5) -> 74.9 | R5: =SUMIFS('A.T D0'!S:S,'A.T D0'!$A:$A,$A5)+SUMIFS('A.T D7'!S:S,'A.T D7'!$A:$A,$A5)+SUMIFS('A.T D22'!S:S,'A.T D22'!$A:$A,$A5)+SUMIFS('A.T D37'!S:S,'A.T D37'!$A:$A,$A5)+SUMIFS('A.T D52'!S:S,'A.T D52'!$A:$A,$A5)+SUMIFS('A.T D67'!S:S,'A.T D67'!$A:$A,$A5) -> 1.07 | S5: =SUMIFS('A.T D0'!T:T,'A.T D0'!$A:$A,$A5)+SUMIFS('A.T D7'!T:T,'A.T D7'!$A:$A,$A5)+SUMIFS('A.T D22'!T:T,'A.T D22'!$A:$A,$A5)+SUMIFS('A.T D37'!T:T,'A.T D37'!$A:$A,$A5)+SUMIFS('A.T D52'!T:T,'A.T D52'!$A:$A,$A5)+SUMIFS('A.T D67'!T:T,'A.T D67'!$A:$A,$A5) -> 11.3623 | T5: =SUMIFS('A.T D0'!U:U,'A.T D0'!$A:$A,$A5)+SUMIFS('A.T D7'!U:U,'A.T D7'!$A:$A,$A5)+SUMIFS('A.T D22'!U:U,'A.T D22'!$A:$A,$A5)+SUMIFS('A.T D37'!U:U,'A.T D37'!$A:$A,$A5)+SUMIFS('A.T D52'!U:U,'A.T D52'!$A:$A,$A5)+SUMIFS('A.T D67'!U:U,'A.T D67'!$A:$A,$A5) -> 0.9 | U5: =SUMIFS('A.T D0'!V:V,'A.T D0'!$A:$A,$A5)+SUMIFS('A.T D7'!V:V,'A.T D7'!$A:$A,$A5)+SUMIFS('A.T D22'!V:V,'A.T D22'!$A:$A,$A5)+SUMIFS('A.T D37'!V:V,'A.T D37'!$A:$A,$A5)+SUMIFS('A.T D52'!V:V,'A.T D52'!$A:$A,$A5)+SUMIFS('A.T D67'!V:V,'A.T D67'!$A:$A,$A5) -> 12.31 | V5: =SUMIFS('A.T D0'!W:W,'A.T D0'!$A:$A,$A5)+SUMIFS('A.T D7'!W:W,'A.T D7'!$A:$A,$A5)+SUMIFS('A.T D22'!W:W,'A.T D22'!$A:$A,$A5)+SUMIFS('A.T D37'!W:W,'A.T D37'!$A:$A,$A5)+SUMIFS('A.T D52'!W:W,'A.T D52'!$A:$A,$A5)+SUMIFS('A.T D67'!W:W,'A.T D67'!$A:$A,$A5) -> -0.77 | W5: =SUMIFS('A.T D0'!X:X,'A.T D0'!$A:$A,$A5)+SUMIFS('A.T D7'!X:X,'A.T D7'!$A:$A,$A5)+SUMIFS('A.T D22'!X:X,'A.T D22'!$A:$A,$A5)+SUMIFS('A.T D37'!X:X,'A.T D37'!$A:$A,$A5)+SUMIFS('A.T D52'!X:X,'A.T D52'!$A:$A,$A5)+SUMIFS('A.T D67'!X:X,'A.T D67'!$A:$A,$A5) -> 117.67 | X5: =SUMIFS(TCH!J:J,TCH!$A:$A,$A5) -> 0 | Y5: =IF(X5=0,0,(X5*AVERAGEIFS($W:$W,$C:$C,$C5,$D:$D,$D5,$E:$E,$E5,$G:$G,$G5,$B:$B,_xlfn.MAXIFS($B:$B,$C:$C,$C5,$D:$D,$D5,$E:$E,$E5,$G:$G,$G5,$B:$B,"<>"&$B5)))/1000) -> 0 | Z5: =SUMIFS(TCH!M:M,TCH!$A:$A,$A5) -> 0 | AA5: =IF(Z5=0,0,(Z5*AVERAGEIFS($W:$W,$C:$C,$C5,$D:$D,$D5,$E:$E,$E5,$G:$G,$G5,$B:$B,_xlfn.MAXIFS($B:$B,$C:$C,$C5,$D:$D,$D5,$E:$E,$E5,$G:$G,$G5,$B:$B,"<>"&$B5)))/1000) -> 0 | AB5: =SUMIFS(TCH!P:P,TCH!$A:$A,$A5) -> 0 | AC5: =IF(AB5=0,0,(AB5*AVERAGEIFS($W:$W,$C:$C,$C5,$D:$D,$D5,$E:$E,$E5,$G:$G,$G5,$B:$B,_xlfn.MAXIFS($B:$B,$C:$C,$C5,$D:$D,$D5,$E:$E,$E5,$G:$G,$G5,$B:$B,"<>"&$B5)))/1000) -> 0 | AD5: =SUMIFS(TCH!S:S,TCH!$A:$A,$A5) -> 0 | AE5: =IF(AD5=0,0,(AD5*AVERAGEIFS($W:$W,$C:$C,$C5,$D:$D,$D5,$E:$E,$E5,$G:$G,$G5,$B:$B,_xlfn.MAXIFS($B:$B,$C:$C,$C5,$D:$D,$D5,$E:$E,$E5,$G:$G,$G5,$B:$B,"<>"&$B5)))/1000) -> 0 | AF5: =SUMIFS(TCH!V:V,TCH!$A:$A,$A5) -> 0 | AG5: =IF(AF5=0,0,(AF5*AVERAGEIFS($W:$W,$C:$C,$C5,$D:$D,$D5,$E:$E,$E5,$G:$G,$G5,$B:$B,_xlfn.MAXIFS($B:$B,$C:$C,$C5,$D:$D,$D5,$E:$E,$E5,$G:$G,$G5,$B:$B,"<>"&$B5)))/1000) -> 0 | AH5: =SUMIFS(TCH!Y:Y,TCH!$A:$A,$A5) -> 0 | AI5: =IF(AH5=0,0,(AH5*AVERAGEIFS($W:$W,$C:$C,$C5,$D:$D,$D5,$E:$E,$E5,$G:$G,$G5,$B:$B,_xlfn.MAXIFS($B:$B,$C:$C,$C5,$D:$D,$D5,$E:$E,$E5,$G:$G,$G5,$B:$B,"<>"&$B5)))/1000) -> 0 | AJ5: 0 | AK5: 0 | AL5: 0 | AM5: 0 | AN5: 0 | AO5: 0 | AP5: 0 | AQ5: 0 | AR5: 0 | AS5: 0 | AT5: 0 | AU5: 0 | AV5: 0 | AW5: 0 | AX5: 0 | AY5: 0 | AZ5: 0
A6: =B6&C6&D6&E6&F6&G6 -> 45733491B3R29 | B6: 45733 | C6: 49 | D6: 1 | E6: B3 | F6: R2 | G6: 9 | H6: =SUMIFS(Biometria!H:H,Biometria!$A:$A,$A6) -> 14 | I6: =SUMIFS(Biometria!I:I,Biometria!$A:$A,$A6) -> 0 | J6: =SUMIFS(Biometria!J:J,Biometria!$A:$A,$A6) -> 0 | K6: =SUMIFS(Biometria!K:K,Biometria!$A:$A,$A6) -> 0 | L6: =SUMIFS(Biometria!L:L,Biometria!$A:$A,$A6) -> 0 | M6: =SUMIFS(Biometria!M:M,Biometria!$A:$A,$A6) -> 0 | N6: =SUMIFS('A.T D0'!O:O,'A.T D0'!$A:$A,$A6)+SUMIFS('A.T D7'!O:O,'A.T D7'!$A:$A,$A6)+SUMIFS('A.T D22'!O:O,'A.T D22'!$A:$A,$A6)+SUMIFS('A.T D37'!O:O,'A.T D37'!$A:$A,$A6)+SUMIFS('A.T D52'!O:O,'A.T D52'!$A:$A,$A6)+SUMIFS('A.T D67'!O:O,'A.T D67'!$A:$A,$A6) -> 5.2 | O6: =SUMIFS('A.T D0'!P:P,'A.T D0'!$A:$A,$A6)+SUMIFS('A.T D7'!P:P,'A.T D7'!$A:$A,$A6)+SUMIFS('A.T D22'!P:P,'A.T D22'!$A:$A,$A6)+SUMIFS('A.T D37'!P:P,'A.T D37'!$A:$A,$A6)+SUMIFS('A.T D52'!P:P,'A.T D52'!$A:$A,$A6)+SUMIFS('A.T D67'!P:P,'A.T D67'!$A:$A,$A6) -> 16.4 | P6: =SUMIFS('A.T D0'!Q:Q,'A.T D0'!$A:$A,$A6)+SUMIFS('A.T D7'!Q:Q,'A.T D7'!$A:$A,$A6)+SUMIFS('A.T D22'!Q:Q,'A.T D22'!$A:$A,$A6)+SUMIFS('A.T D37'!Q:Q,'A.T D37'!$A:$A,$A6)+SUMIFS('A.T D52'!Q:Q,'A.T D52'!$A:$A,$A6)+SUMIFS('A.T D67'!Q:Q,'A.T D67'!$A:$A,$A6) -> 12.24 | Q6: =SUMIFS('A.T D0'!R:R,'A.T D0'!$A:$A,$A6)+SUMIFS('A.T D7'!R:R,'A.T D7'!$A:$A,$A6)+SUMIFS('A.T D22'!R:R,'A.T D22'!$A:$A,$A6)+SUMIFS('A.T D37'!R:R,'A.T D37'!$A:$A,$A6)+SUMIFS('A.T D52'!R:R,'A.T D52'!$A:$A,$A6)+SUMIFS('A.T D67'!R:R,'A.T D67'!$A:$A,$A6) -> 74.63 | R6: =SUMIFS('A.T D0'!S:S,'A.T D0'!$A:$A,$A6)+SUMIFS('A.T D7'!S:S,'A.T D7'!$A:$A,$A6)+SUMIFS('A.T D22'!S:S,'A.T D22'!$A:$A,$A6)+SUMIFS('A.T D37'!S:S,'A.T D37'!$A:$A,$A6)+SUMIFS('A.T D52'!S:S,'A.T D52'!$A:$A,$A6)+SUMIFS('A.T D67'!S:S,'A.T D67'!$A:$A,$A6) -> 1.08 | S6: =SUMIFS('A.T D0'!T:T,'A.T D0'!$A:$A,$A6)+SUMIFS('A.T D7'!T:T,'A.T D7'!$A:$A,$A6)+SUMIFS('A.T D22'!T:T,'A.T D22'!$A:$A,$A6)+SUMIFS('A.T D37'!T:T,'A.T D37'!$A:$A,$A6)+SUMIFS('A.T D52'!T:T,'A.T D52'!$A:$A,$A6)+SUMIFS('A.T D67'!T:T,'A.T D67'!$A:$A,$A6) -> 10.2004 | T6: =SUMIFS('A.T D0'!U:U,'A.T D0'!$A:$A,$A6)+SUMIFS('A.T D7'!U:U,'A.T D7'!$A:$A,$A6)+SUMIFS('A.T D22'!U:U,'A.T D22'!$A:$A,$A6)+SUMIFS('A.T D37'!U:U,'A.T D37'!$A:$A,$A6)+SUMIFS('A.T D52'!U:U,'A.T D52'!$A:$A,$A6)+SUMIFS('A.T D67'!U:U,'A.T D67'!$A:$A,$A6) -> 0.9 | U6: =SUMIFS('A.T D0'!V:V,'A.T D0'!$A:$A,$A6)+SUMIFS('A.T D7'!V:V,'A.T D7'!$A:$A,$A6)+SUMIFS('A.T D22'!V:V,'A.T D22'!$A:$A,$A6)+SUMIFS('A.T D37'!V:V,'A.T D37'!$A:$A,$A6)+SUMIFS('A.T D52'!V:V,'A.T D52'!$A:$A,$A6)+SUMIFS('A.T D67'!V:V,'A.T D67'!$A:$A,$A6) -> 12.92 | V6: =SUMIFS('A.T D0'!W:W,'A.T D0'!$A:$A,$A6)+SUMIFS('A.T D7'!W:W,'A.T D7'!$A:$A,$A6)+SUMIFS('A.T D22'!W:W,'A.T D22'!$A:$A,$A6)+SUMIFS('A.T D37'!W:W,'A.T D37'!$A:$A,$A6)+SUMIFS('A.T D52'!W:W,'A.T D52'!$A:$A,$A6)+SUMIFS('A.T D67'!W:W,'A.T D67'!$A:$A,$A6) -> -10.2 | W6: =SUMIFS('A.T D0'!X:X,'A.T D0'!$A:$A,$A6)+SUMIFS('A.T D7'!X:X,'A.T D7'!$A:$A,$A6)+SUMIFS('A.T D22'!X:X,'A.T D22'!$A:$A,$A6)+SUMIFS('A.T D37'!X:X,'A.T D37'!$A:$A,$A6)+SUMIFS('A.T D52'!X:X,'A.T D52'!$A:$A,$A6)+SUMIFS('A.T D67'!X:X,'A.T D67'!$A:$A,$A6) -> 106.48 | X6: =SUMIFS(TCH!J:J,TCH!$A:$A,$A6) -> 0 | Y6: =IF(X6=0,0,(X6*AVERAGEIFS($W:$W,$C:$C,$C6,$D:$D,$D6,$E:$E,$E6,$G:$G,$G6,$B:$B,_xlfn.MAXIFS($B:$B,$C:$C,$C6,$D:$D,$D6,$E:$E,$E6,$G:$G,$G6,$B:$B,"<>"&$B6)))/1000) -> 0 | Z6: =SUMIFS(TCH!M:M,TCH!$A:$A,$A6) -> 0 | AA6: =IF(Z6=0,0,(Z6*AVERAGEIFS($W:$W,$C:$C,$C6,$D:$D,$D6,$E:$E,$E6,$G:$G,$G6,$B:$B,_xlfn.MAXIFS($B:$B,$C:$C,$C6,$D:$D,$D6,$E:$E,$E6,$G:$G,$G6,$B:$B,"<>"&$B6)))/1000) -> 0 | AB6: =SUMIFS(TCH!P:P,TCH!$A:$A,$A6) -> 0 | AC6: =IF(AB6=0,0,(AB6*AVERAGEIFS($W:$W,$C:$C,$C6,$D:$D,$D6,$E:$E,$E6,$G:$G,$G6,$B:$B,_xlfn.MAXIFS($B:$B,$C:$C,$C6,$D:$D,$D6,$E:$E,$E6,$G:$G,$G6,$B:$B,"<>"&$B6)))/1000) -> 0 | AD6: =SUMIFS(TCH!S:S,TCH!$A:$A,$A6) -> 0 | AE6: =IF(AD6=0,0,(AD6*AVERAGEIFS($W:$W,$C:$C,$C6,$D:$D,$D6,$E:$E,$E6,$G:$G,$G6,$B:$B,_xlfn.MAXIFS($B:$B,$C:$C,$C6,$D:$D,$D6,$E:$E,$E6,$G:$G,$G6,$B:$B,"<>"&$B6)))/1000) -> 0 | AF6: =SUMIFS(TCH!V:V,TCH!$A:$A,$A6) -> 0 | AG6: =IF(AF6=0,0,(AF6*AVERAGEIFS($W:$W,$C:$C,$C6,$D:$D,$D6,$E:$E,$E6,$G:$G,$G6,$B:$B,_xlfn.MAXIFS($B:$B,$C:$C,$C6,$D:$D,$D6,$E:$E,$E6,$G:$G,$G6,$B:$B,"<>"&$B6)))/1000) -> 0 | AH6: =SUMIFS(TCH!Y:Y,TCH!$A:$A,$A6) -> 0 | AI6: =IF(AH6=0,0,(AH6*AVERAGEIFS($W:$W,$C:$C,$C6,$D:$D,$D6,$E:$E,$E6,$G:$G,$G6,$B:$B,_xlfn.MAXIFS($B:$B,$C:$C,$C6,$D:$D,$D6,$E:$E,$E6,$G:$G,$G6,$B:$B,"<>"&$B6)))/1000) -> 0 | AJ6: 0 | AK6: 0 | AL6: 0 | AM6: 0 | AN6: 0 | AO6: 0 | AP6: 0 | AQ6: 0 | AR6: 0 | AS6: 0 | AT6: 0 | AU6: 0 | AV6: 0 | AW6: 0 | AX6: 0 | AY6: 0 | AZ6: 0
A7: =B7&C7&D7&E7&F7&G7 -> 45733491B3R39 | B7: 45733 | C7: 49 | D7: 1 | E7: B3 | F7: R3 | G7: 9 | H7: =SUMIFS(Biometria!H:H,Biometria!$A:$A,$A7) -> 13.49 | I7: =SUMIFS(Biometria!I:I,Biometria!$A:$A,$A7) -> 0 | J7: =SUMIFS(Biometria!J:J,Biometria!$A:$A,$A7) -> 0 | K7: =SUMIFS(Biometria!K:K,Biometria!$A:$A,$A7) -> 0 | L7: =SUMIFS(Biometria!L:L,Biometria!$A:$A,$A7) -> 0 | M7: =SUMIFS(Biometria!M:M,Biometria!$A:$A,$A7) -> 0 | N7: =SUMIFS('A.T D0'!O:O,'A.T D0'!$A:$A,$A7)+SUMIFS('A.T D7'!O:O,'A.T D7'!$A:$A,$A7)+SUMIFS('A.T D22'!O:O,'A.T D22'!$A:$A,$A7)+SUMIFS('A.T D37'!O:O,'A.T D37'!$A:$A,$A7)+SUMIFS('A.T D52'!O:O,'A.T D52'!$A:$A,$A7)+SUMIFS('A.T D67'!O:O,'A.T D67'!$A:$A,$A7) -> 5.2 | O7: =SUMIFS('A.T D0'!P:P,'A.T D0'!$A:$A,$A7)+SUMIFS('A.T D7'!P:P,'A.T D7'!$A:$A,$A7)+SUMIFS('A.T D22'!P:P,'A.T D22'!$A:$A,$A7)+SUMIFS('A.T D37'!P:P,'A.T D37'!$A:$A,$A7)+SUMIFS('A.T D52'!P:P,'A.T D52'!$A:$A,$A7)+SUMIFS('A.T D67'!P:P,'A.T D67'!$A:$A,$A7) -> 16.44 | P7: =SUMIFS('A.T D0'!Q:Q,'A.T D0'!$A:$A,$A7)+SUMIFS('A.T D7'!Q:Q,'A.T D7'!$A:$A,$A7)+SUMIFS('A.T D22'!Q:Q,'A.T D22'!$A:$A,$A7)+SUMIFS('A.T D37'!Q:Q,'A.T D37'!$A:$A,$A7)+SUMIFS('A.T D52'!Q:Q,'A.T D52'!$A:$A,$A7)+SUMIFS('A.T D67'!Q:Q,'A.T D67'!$A:$A,$A7) -> 12.22 | Q7: =SUMIFS('A.T D0'!R:R,'A.T D0'!$A:$A,$A7)+SUMIFS('A.T D7'!R:R,'A.T D7'!$A:$A,$A7)+SUMIFS('A.T D22'!R:R,'A.T D22'!$A:$A,$A7)+SUMIFS('A.T D37'!R:R,'A.T D37'!$A:$A,$A7)+SUMIFS('A.T D52'!R:R,'A.T D52'!$A:$A,$A7)+SUMIFS('A.T D67'!R:R,'A.T D67'!$A:$A,$A7) -> 74.33 | R7: =SUMIFS('A.T D0'!S:S,'A.T D0'!$A:$A,$A7)+SUMIFS('A.T D7'!S:S,'A.T D7'!$A:$A,$A7)+SUMIFS('A.T D22'!S:S,'A.T D22'!$A:$A,$A7)+SUMIFS('A.T D37'!S:S,'A.T D37'!$A:$A,$A7)+SUMIFS('A.T D52'!S:S,'A.T D52'!$A:$A,$A7)+SUMIFS('A.T D67'!S:S,'A.T D67'!$A:$A,$A7) -> 1.09 | S7: =SUMIFS('A.T D0'!T:T,'A.T D0'!$A:$A,$A7)+SUMIFS('A.T D7'!T:T,'A.T D7'!$A:$A,$A7)+SUMIFS('A.T D22'!T:T,'A.T D22'!$A:$A,$A7)+SUMIFS('A.T D37'!T:T,'A.T D37'!$A:$A,$A7)+SUMIFS('A.T D52'!T:T,'A.T D52'!$A:$A,$A7)+SUMIFS('A.T D67'!T:T,'A.T D67'!$A:$A,$A7) -> 10.3697 | T7: =SUMIFS('A.T D0'!U:U,'A.T D0'!$A:$A,$A7)+SUMIFS('A.T D7'!U:U,'A.T D7'!$A:$A,$A7)+SUMIFS('A.T D22'!U:U,'A.T D22'!$A:$A,$A7)+SUMIFS('A.T D37'!U:U,'A.T D37'!$A:$A,$A7)+SUMIFS('A.T D52'!U:U,'A.T D52'!$A:$A,$A7)+SUMIFS('A.T D67'!U:U,'A.T D67'!$A:$A,$A7) -> 0.92 | U7: =SUMIFS('A.T D0'!V:V,'A.T D0'!$A:$A,$A7)+SUMIFS('A.T D7'!V:V,'A.T D7'!$A:$A,$A7)+SUMIFS('A.T D22'!V:V,'A.T D22'!$A:$A,$A7)+SUMIFS('A.T D37'!V:V,'A.T D37'!$A:$A,$A7)+SUMIFS('A.T D52'!V:V,'A.T D52'!$A:$A,$A7)+SUMIFS('A.T D67'!V:V,'A.T D67'!$A:$A,$A7) -> 11.88 | V7: =SUMIFS('A.T D0'!W:W,'A.T D0'!$A:$A,$A7)+SUMIFS('A.T D7'!W:W,'A.T D7'!$A:$A,$A7)+SUMIFS('A.T D22'!W:W,'A.T D22'!$A:$A,$A7)+SUMIFS('A.T D37'!W:W,'A.T D37'!$A:$A,$A7)+SUMIFS('A.T D52'!W:W,'A.T D52'!$A:$A,$A7)+SUMIFS('A.T D67'!W:W,'A.T D67'!$A:$A,$A7) -> -8.68 | W7: =SUMIFS('A.T D0'!X:X,'A.T D0'!$A:$A,$A7)+SUMIFS('A.T D7'!X:X,'A.T D7'!$A:$A,$A7)+SUMIFS('A.T D22'!X:X,'A.T D22'!$A:$A,$A7)+SUMIFS('A.T D37'!X:X,'A.T D37'!$A:$A,$A7)+SUMIFS('A.T D52'!X:X,'A.T D52'!$A:$A,$A7)+SUMIFS('A.T D67'!X:X,'A.T D67'!$A:$A,$A7) -> 108.29 | X7: =SUMIFS(TCH!J:J,TCH!$A:$A,$A7) -> 0 | Y7: =IF(X7=0,0,(X7*AVERAGEIFS($W:$W,$C:$C,$C7,$D:$D,$D7,$E:$E,$E7,$G:$G,$G7,$B:$B,_xlfn.MAXIFS($B:$B,$C:$C,$C7,$D:$D,$D7,$E:$E,$E7,$G:$G,$G7,$B:$B,"<>"&$B7)))/1000) -> 0 | Z7: =SUMIFS(TCH!M:M,TCH!$A:$A,$A7) -> 0 | AA7: =IF(Z7=0,0,(Z7*AVERAGEIFS($W:$W,$C:$C,$C7,$D:$D,$D7,$E:$E,$E7,$G:$G,$G7,$B:$B,_xlfn.MAXIFS($B:$B,$C:$C,$C7,$D:$D,$D7,$E:$E,$E7,$G:$G,$G7,$B:$B,"<>"&$B7)))/1000) -> 0 | AB7: =SUMIFS(TCH!P:P,TCH!$A:$A,$A7) -> 0 | AC7: =IF(AB7=0,0,(AB7*AVERAGEIFS($W:$W,$C:$C,$C7,$D:$D,$D7,$E:$E,$E7,$G:$G,$G7,$B:$B,_xlfn.MAXIFS($B:$B,$C:$C,$C7,$D:$D,$D7,$E:$E,$E7,$G:$G,$G7,$B:$B,"<>"&$B7)))/1000) -> 0 | AD7: =SUMIFS(TCH!S:S,TCH!$A:$A,$A7) -> 0 | AE7: =IF(AD7=0,0,(AD7*AVERAGEIFS($W:$W,$C:$C,$C7,$D:$D,$D7,$E:$E,$E7,$G:$G,$G7,$B:$B,_xlfn.MAXIFS($B:$B,$C:$C,$C7,$D:$D,$D7,$E:$E,$E7,$G:$G,$G7,$B:$B,"<>"&$B7)))/1000) -> 0 | AF7: =SUMIFS(TCH!V:V,TCH!$A:$A,$A7) -> 0 | AG7: =IF(AF7=0,0,(AF7*AVERAGEIFS($W:$W,$C:$C,$C7,$D:$D,$D7,$E:$E,$E7,$G:$G,$G7,$B:$B,_xlfn.MAXIFS($B:$B,$C:$C,$C7,$D:$D,$D7,$E:$E,$E7,$G:$G,$G7,$B:$B,"<>"&$B7)))/1000) -> 0 | AH7: =SUMIFS(TCH!Y:Y,TCH!$A:$A,$A7) -> 0 | AI7: =IF(AH7=0,0,(AH7*AVERAGEIFS($W:$W,$C:$C,$C7,$D:$D,$D7,$E:$E,$E7,$G:$G,$G7,$B:$B,_xlfn.MAXIFS($B:$B,$C:$C,$C7,$D:$D,$D7,$E:$E,$E7,$G:$G,$G7,$B:$B,"<>"&$B7)))/1000) -> 0 | AJ7: 0 | AK7: 0 | AL7: 0 | AM7: 0 | AN7: 0 | AO7: 0 | AP7: 0 | AQ7: 0 | AR7: 0 | AS7: 0 | AT7: 0 | AU7: 0 | AV7: 0 | AW7: 0 | AX7: 0 | AY7: 0 | AZ7: 0
A8: =B8&C8&D8&E8&F8&G8 -> 45733491B2R117 | B8: 45733 | C8: 49 | D8: 1 | E8: B2 | F8: R1 | G8: 17 | H8: =SUMIFS(Biometria!H:H,Biometria!$A:$A,$A8) -> 16.62 | I8: =SUMIFS(Biometria!I:I,Biometria!$A:$A,$A8) -> 17.173333 | J8: =SUMIFS(Biometria!J:J,Biometria!$A:$A,$A8) -> 0 | K8: =SUMIFS(Biometria!K:K,Biometria!$A:$A,$A8) -> 2.62 | L8: =SUMIFS(Biometria!L:L,Biometria!$A:$A,$A8) -> 0 | M8: =SUMIFS(Biometria!M:M,Biometria!$A:$A,$A8) -> 0 | N8: =SUMIFS('A.T D0'!O:O,'A.T D0'!$A:$A,$A8)+SUMIFS('A.T D7'!O:O,'A.T D7'!$A:$A,$A8)+SUMIFS('A.T D22'!O:O,'A.T D22'!$A:$A,$A8)+SUMIFS('A.T D37'!O:O,'A.T D37'!$A:$A,$A8)+SUMIFS('A.T D52'!O:O,'A.T D52'!$A:$A,$A8)+SUMIFS('A.T D67'!O:O,'A.T D67'!$A:$A,$A8) -> 5.2 | O8: =SUMIFS('A.T D0'!P:P,'A.T D0'!$A:$A,$A8)+SUMIFS('A.T D7'!P:P,'A.T D7'!$A:$A,$A8)+SUMIFS('A.T D22'!P:P,'A.T D22'!$A:$A,$A8)+SUMIFS('A.T D37'!P:P,'A.T D37'!$A:$A,$A8)+SUMIFS('A.T D52'!P:P,'A.T D52'!$A:$A,$A8)+SUMIFS('A.T D67'!P:P,'A.T D67'!$A:$A,$A8) -> 16.4 | P8: =SUMIFS('A.T D0'!Q:Q,'A.T D0'!$A:$A,$A8)+SUMIFS('A.T D7'!Q:Q,'A.T D7'!$A:$A,$A8)+SUMIFS('A.T D22'!Q:Q,'A.T D22'!$A:$A,$A8)+SUMIFS('A.T D37'!Q:Q,'A.T D37'!$A:$A,$A8)+SUMIFS('A.T D52'!Q:Q,'A.T D52'!$A:$A,$A8)+SUMIFS('A.T D67'!Q:Q,'A.T D67'!$A:$A,$A8) -> 12.44 | Q8: =SUMIFS('A.T D0'!R:R,'A.T D0'!$A:$A,$A8)+SUMIFS('A.T D7'!R:R,'A.T D7'!$A:$A,$A8)+SUMIFS('A.T D22'!R:R,'A.T D22'!$A:$A,$A8)+SUMIFS('A.T D37'!R:R,'A.T D37'!$A:$A,$A8)+SUMIFS('A.T D52'!R:R,'A.T D52'!$A:$A,$A8)+SUMIFS('A.T D67'!R:R,'A.T D67'!$A:$A,$A8) -> 75.85 | R8: =SUMIFS('A.T D0'!S:S,'A.T D0'!$A:$A,$A8)+SUMIFS('A.T D7'!S:S,'A.T D7'!$A:$A,$A8)+SUMIFS('A.T D22'!S:S,'A.T D22'!$A:$A,$A8)+SUMIFS('A.T D37'!S:S,'A.T D37'!$A:$A,$A8)+SUMIFS('A.T D52'!S:S,'A.T D52'!$A:$A,$A8)+SUMIFS('A.T D67'!S:S,'A.T D67'!$A:$A,$A8) -> 1.04 | S8: =SUMIFS('A.T D0'!T:T,'A.T D0'!$A:$A,$A8)+SUMIFS('A.T D7'!T:T,'A.T D7'!$A:$A,$A8)+SUMIFS('A.T D22'!T:T,'A.T D22'!$A:$A,$A8)+SUMIFS('A.T D37'!T:T,'A.T D37'!$A:$A,$A8)+SUMIFS('A.T D52'!T:T,'A.T D52'!$A:$A,$A8)+SUMIFS('A.T D67'!T:T,'A.T D67'!$A:$A,$A8) -> 10.3979 | T8: =SUMIFS('A.T D0'!U:U,'A.T D0'!$A:$A,$A8)+SUMIFS('A.T D7'!U:U,'A.T D7'!$A:$A,$A8)+SUMIFS('A.T D22'!U:U,'A.T D22'!$A:$A,$A8)+SUMIFS('A.T D37'!U:U,'A.T D37'!$A:$A,$A8)+SUMIFS('A.T D52'!U:U,'A.T D52'!$A:$A,$A8)+SUMIFS('A.T D67'!U:U,'A.T D67'!$A:$A,$A8) -> 0.87 | U8: =SUMIFS('A.T D0'!V:V,'A.T D0'!$A:$A,$A8)+SUMIFS('A.T D7'!V:V,'A.T D7'!$A:$A,$A8)+SUMIFS('A.T D22'!V:V,'A.T D22'!$A:$A,$A8)+SUMIFS('A.T D37'!V:V,'A.T D37'!$A:$A,$A8)+SUMIFS('A.T D52'!V:V,'A.T D52'!$A:$A,$A8)+SUMIFS('A.T D67'!V:V,'A.T D67'!$A:$A,$A8) -> 12.75 | V8: =SUMIFS('A.T D0'!W:W,'A.T D0'!$A:$A,$A8)+SUMIFS('A.T D7'!W:W,'A.T D7'!$A:$A,$A8)+SUMIFS('A.T D22'!W:W,'A.T D22'!$A:$A,$A8)+SUMIFS('A.T D37'!W:W,'A.T D37'!$A:$A,$A8)+SUMIFS('A.T D52'!W:W,'A.T D52'!$A:$A,$A8)+SUMIFS('A.T D67'!W:W,'A.T D67'!$A:$A,$A8) -> -8.83 | W8: =SUMIFS('A.T D0'!X:X,'A.T D0'!$A:$A,$A8)+SUMIFS('A.T D7'!X:X,'A.T D7'!$A:$A,$A8)+SUMIFS('A.T D22'!X:X,'A.T D22'!$A:$A,$A8)+SUMIFS('A.T D37'!X:X,'A.T D37'!$A:$A,$A8)+SUMIFS('A.T D52'!X:X,'A.T D52'!$A:$A,$A8)+SUMIFS('A.T D67'!X:X,'A.T D67'!$A:$A,$A8) -> 108.11 | X8: =SUMIFS(TCH!J:J,TCH!$A:$A,$A8) -> 0 | Y8: =IF(X8=0,0,(X8*AVERAGEIFS($W:$W,$C:$C,$C8,$D:$D,$D8,$E:$E,$E8,$G:$G,$G8,$B:$B,_xlfn.MAXIFS($B:$B,$C:$C,$C8,$D:$D,$D8,$E:$E,$E8,$G:$G,$G8,$B:$B,"<>"&$B8)))/1000) -> 0 | Z8: =SUMIFS(TCH!M:M,TCH!$A:$A,$A8) -> 0 | AA8: =IF(Z8=0,0,(Z8*AVERAGEIFS($W:$W,$C:$C,$C8,$D:$D,$D8,$E:$E,$E8,$G:$G,$G8,$B:$B,_xlfn.MAXIFS($B:$B,$C:$C,$C8,$D:$D,$D8,$E:$E,$E8,$G:$G,$G8,$B:$B,"<>"&$B8)))/1000) -> 0 | AB8: =SUMIFS(TCH!P:P,TCH!$A:$A,$A8) -> 0 | AC8: =IF(AB8=0,0,(AB8*AVERAGEIFS($W:$W,$C:$C,$C8,$D:$D,$D8,$E:$E,$E8,$G:$G,$G8,$B:$B,_xlfn.MAXIFS($B:$B,$C:$C,$C8,$D:$D,$D8,$E:$E,$E8,$G:$G,$G8,$B:$B,"<>"&$B8)))/1000) -> 0 | AD8: =SUMIFS(TCH!S:S,TCH!$A:$A,$A8) -> 0 | AE8: =IF(AD8=0,0,(AD8*AVERAGEIFS($W:$W,$C:$C,$C8,$D:$D,$D8,$E:$E,$E8,$G:$G,$G8,$B:$B,_xlfn.MAXIFS($B:$B,$C:$C,$C8,$D:$D,$D8,$E:$E,$E8,$G:$G,$G8,$B:$B,"<>"&$B8)))/1000) -> 0 | AF8: =SUMIFS(TCH!V:V,TCH!$A:$A,$A8) -> 0 | AG8: =IF(AF8=0,0,(AF8*AVERAGEIFS($W:$W,$C:$C,$C8,$D:$D,$D8,$E:$E,$E8,$G:$G,$G8,$B:$B,_xlfn.MAXIFS($B:$B,$C:$C,$C8,$D:$D,$D8,$E:$E,$E8,$G:$G,$G8,$B:$B,"<>"&$B8)))/1000) -> 0 | AH8: =SUMIFS(TCH!Y:Y,TCH!$A:$A,$A8) -> 0 | AI8: =IF(AH8=0,0,(AH8*AVERAGEIFS($W:$W,$C:$C,$C8,$D:$D,$D8,$E:$E,$E8,$G:$G,$G8,$B:$B,_xlfn.MAXIFS($B:$B,$C:$C,$C8,$D:$D,$D8,$E:$E,$E8,$G:$G,$G8,$B:$B,"<>"&$B8)))/1000) -> 0 | AJ8: 0 | AK8: 0 | AL8: 0 | AM8: 0 | AN8: 0 | AO8: 0 | AP8: 0 | AQ8: 0 | AR8: 0 | AS8: 0 | AT8: 0 | AU8: 0 | AV8: 0 | AW8: 0 | AX8: 0 | AY8: 0 | AZ8: 0
A9: =B9&C9&D9&E9&F9&G9 -> 45733491B2R217 | B9: 45733 | C9: 49 | D9: 1 | E9: B2 | F9: R2 | G9: 17 | H9: =SUMIFS(Biometria!H:H,Biometria!$A:$A,$A9) -> 18.41 | I9: =SUMIFS(Biometria!I:I,Biometria!$A:$A,$A9) -> 0 | J9: =SUMIFS(Biometria!J:J,Biometria!$A:$A,$A9) -> 0 | K9: =SUMIFS(Biometria!K:K,Biometria!$A:$A,$A9) -> 0 | L9: =SUMIFS(Biometria!L:L,Biometria!$A:$A,$A9) -> 0 | M9: =SUMIFS(Biometria!M:M,Biometria!$A:$A,$A9) -> 0 | N9: =SUMIFS('A.T D0'!O:O,'A.T D0'!$A:$A,$A9)+SUMIFS('A.T D7'!O:O,'A.T D7'!$A:$A,$A9)+SUMIFS('A.T D22'!O:O,'A.T D22'!$A:$A,$A9)+SUMIFS('A.T D37'!O:O,'A.T D37'!$A:$A,$A9)+SUMIFS('A.T D52'!O:O,'A.T D52'!$A:$A,$A9)+SUMIFS('A.T D67'!O:O,'A.T D67'!$A:$A,$A9) -> 5.2 | O9: =SUMIFS('A.T D0'!P:P,'A.T D0'!$A:$A,$A9)+SUMIFS('A.T D7'!P:P,'A.T D7'!$A:$A,$A9)+SUMIFS('A.T D22'!P:P,'A.T D22'!$A:$A,$A9)+SUMIFS('A.T D37'!P:P,'A.T D37'!$A:$A,$A9)+SUMIFS('A.T D52'!P:P,'A.T D52'!$A:$A,$A9)+SUMIFS('A.T D67'!P:P,'A.T D67'!$A:$A,$A9) -> 16.27 | P9: =SUMIFS('A.T D0'!Q:Q,'A.T D0'!$A:$A,$A9)+SUMIFS('A.T D7'!Q:Q,'A.T D7'!$A:$A,$A9)+SUMIFS('A.T D22'!Q:Q,'A.T D22'!$A:$A,$A9)+SUMIFS('A.T D37'!Q:Q,'A.T D37'!$A:$A,$A9)+SUMIFS('A.T D52'!Q:Q,'A.T D52'!$A:$A,$A9)+SUMIFS('A.T D67'!Q:Q,'A.T D67'!$A:$A,$A9) -> 11.77 | Q9: =SUMIFS('A.T D0'!R:R,'A.T D0'!$A:$A,$A9)+SUMIFS('A.T D7'!R:R,'A.T D7'!$A:$A,$A9)+SUMIFS('A.T D22'!R:R,'A.T D22'!$A:$A,$A9)+SUMIFS('A.T D37'!R:R,'A.T D37'!$A:$A,$A9)+SUMIFS('A.T D52'!R:R,'A.T D52'!$A:$A,$A9)+SUMIFS('A.T D67'!R:R,'A.T D67'!$A:$A,$A9) -> 72.34 | R9: =SUMIFS('A.T D0'!S:S,'A.T D0'!$A:$A,$A9)+SUMIFS('A.T D7'!S:S,'A.T D7'!$A:$A,$A9)+SUMIFS('A.T D22'!S:S,'A.T D22'!$A:$A,$A9)+SUMIFS('A.T D37'!S:S,'A.T D37'!$A:$A,$A9)+SUMIFS('A.T D52'!S:S,'A.T D52'!$A:$A,$A9)+SUMIFS('A.T D67'!S:S,'A.T D67'!$A:$A,$A9) -> 1.16 | S9: =SUMIFS('A.T D0'!T:T,'A.T D0'!$A:$A,$A9)+SUMIFS('A.T D7'!T:T,'A.T D7'!$A:$A,$A9)+SUMIFS('A.T D22'!T:T,'A.T D22'!$A:$A,$A9)+SUMIFS('A.T D37'!T:T,'A.T D37'!$A:$A,$A9)+SUMIFS('A.T D52'!T:T,'A.T D52'!$A:$A,$A9)+SUMIFS('A.T D67'!T:T,'A.T D67'!$A:$A,$A9) -> 9.7984 | T9: =SUMIFS('A.T D0'!U:U,'A.T D0'!$A:$A,$A9)+SUMIFS('A.T D7'!U:U,'A.T D7'!$A:$A,$A9)+SUMIFS('A.T D22'!U:U,'A.T D22'!$A:$A,$A9)+SUMIFS('A.T D37'!U:U,'A.T D37'!$A:$A,$A9)+SUMIFS('A.T D52'!U:U,'A.T D52'!$A:$A,$A9)+SUMIFS('A.T D67'!U:U,'A.T D67'!$A:$A,$A9) -> 0.97 | U9: =SUMIFS('A.T D0'!V:V,'A.T D0'!$A:$A,$A9)+SUMIFS('A.T D7'!V:V,'A.T D7'!$A:$A,$A9)+SUMIFS('A.T D22'!V:V,'A.T D22'!$A:$A,$A9)+SUMIFS('A.T D37'!V:V,'A.T D37'!$A:$A,$A9)+SUMIFS('A.T D52'!V:V,'A.T D52'!$A:$A,$A9)+SUMIFS('A.T D67'!V:V,'A.T D67'!$A:$A,$A9) -> 12.98 | V9: =SUMIFS('A.T D0'!W:W,'A.T D0'!$A:$A,$A9)+SUMIFS('A.T D7'!W:W,'A.T D7'!$A:$A,$A9)+SUMIFS('A.T D22'!W:W,'A.T D22'!$A:$A,$A9)+SUMIFS('A.T D37'!W:W,'A.T D37'!$A:$A,$A9)+SUMIFS('A.T D52'!W:W,'A.T D52'!$A:$A,$A9)+SUMIFS('A.T D67'!W:W,'A.T D67'!$A:$A,$A9) -> -12.93 | W9: =SUMIFS('A.T D0'!X:X,'A.T D0'!$A:$A,$A9)+SUMIFS('A.T D7'!X:X,'A.T D7'!$A:$A,$A9)+SUMIFS('A.T D22'!X:X,'A.T D22'!$A:$A,$A9)+SUMIFS('A.T D37'!X:X,'A.T D37'!$A:$A,$A9)+SUMIFS('A.T D52'!X:X,'A.T D52'!$A:$A,$A9)+SUMIFS('A.T D67'!X:X,'A.T D67'!$A:$A,$A9) -> 103.25 | X9: =SUMIFS(TCH!J:J,TCH!$A:$A,$A9) -> 0 | Y9: =IF(X9=0,0,(X9*AVERAGEIFS($W:$W,$C:$C,$C9,$D:$D,$D9,$E:$E,$E9,$G:$G,$G9,$B:$B,_xlfn.MAXIFS($B:$B,$C:$C,$C9,$D:$D,$D9,$E:$E,$E9,$G:$G,$G9,$B:$B,"<>"&$B9)))/1000) -> 0 | Z9: =SUMIFS(TCH!M:M,TCH!$A:$A,$A9) -> 0 | AA9: =IF(Z9=0,0,(Z9*AVERAGEIFS($W:$W,$C:$C,$C9,$D:$D,$D9,$E:$E,$E9,$G:$G,$G9,$B:$B,_xlfn.MAXIFS($B:$B,$C:$C,$C9,$D:$D,$D9,$E:$E,$E9,$G:$G,$G9,$B:$B,"<>"&$B9)))/1000) -> 0 | AB9: =SUMIFS(TCH!P:P,TCH!$A:$A,$A9) -> 0 | AC9: =IF(AB9=0,0,(AB9*AVERAGEIFS($W:$W,$C:$C,$C9,$D:$D,$D9,$E:$E,$E9,$G:$G,$G9,$B:$B,_xlfn.MAXIFS($B:$B,$C:$C,$C9,$D:$D,$D9,$E:$E,$E9,$G:$G,$G9,$B:$B,"<>"&$B9)))/1000) -> 0 | AD9: =SUMIFS(TCH!S:S,TCH!$A:$A,$A9) -> 0 | AE9: =IF(AD9=0,0,(AD9*AVERAGEIFS($W:$W,$C:$C,$C9,$D:$D,$D9,$E:$E,$E9,$G:$G,$G9,$B:$B,_xlfn.MAXIFS($B:$B,$C:$C,$C9,$D:$D,$D9,$E:$E,$E9,$G:$G,$G9,$B:$B,"<>"&$B9)))/1000) -> 0 | AF9: =SUMIFS(TCH!V:V,TCH!$A:$A,$A9) -> 0 | AG9: =IF(AF9=0,0,(AF9*AVERAGEIFS($W:$W,$C:$C,$C9,$D:$D,$D9,$E:$E,$E9,$G:$G,$G9,$B:$B,_xlfn.MAXIFS($B:$B,$C:$C,$C9,$D:$D,$D9,$E:$E,$E9,$G:$G,$G9,$B:$B,"<>"&$B9)))/1000) -> 0 | AH9: =SUMIFS(TCH!Y:Y,TCH!$A:$A,$A9) -> 0 | AI9: =IF(AH9=0,0,(AH9*AVERAGEIFS($W:$W,$C:$C,$C9,$D:$D,$D9,$E:$E,$E9,$G:$G,$G9,$B:$B,_xlfn.MAXIFS($B:$B,$C:$C,$C9,$D:$D,$D9,$E:$E,$E9,$G:$G,$G9,$B:$B,"<>"&$B9)))/1000) -> 0 | AJ9: 0 | AK9: 0 | AL9: 0 | AM9: 0 | AN9: 0 | AO9: 0 | AP9: 0 | AQ9: 0 | AR9: 0 | AS9: 0 | AT9: 0 | AU9: 0 | AV9: 0 | AW9: 0 | AX9: 0 | AY9: 0 | AZ9: 0
A10: =B10&C10&D10&E10&F10&G10 -> 45733491B2R317 | B10: 45733 | C10: 49 | D10: 1 | E10: B2 | F10: R3 | G10: 17 | H10: =SUMIFS(Biometria!H:H,Biometria!$A:$A,$A10) -> 16.49 | I10: =SUMIFS(Biometria!I:I,Biometria!$A:$A,$A10) -> 0 | J10: =SUMIFS(Biometria!J:J,Biometria!$A:$A,$A10) -> 0 | K10: =SUMIFS(Biometria!K:K,Biometria!$A:$A,$A10) -> 0 | L10: =SUMIFS(Biometria!L:L,Biometria!$A:$A,$A10) -> 0 | M10: =SUMIFS(Biometria!M:M,Biometria!$A:$A,$A10) -> 0 | N10: =SUMIFS('A.T D0'!O:O,'A.T D0'!$A:$A,$A10)+SUMIFS('A.T D7'!O:O,'A.T D7'!$A:$A,$A10)+SUMIFS('A.T D22'!O:O,'A.T D22'!$A:$A,$A10)+SUMIFS('A.T D37'!O:O,'A.T D37'!$A:$A,$A10)+SUMIFS('A.T D52'!O:O,'A.T D52'!$A:$A,$A10)+SUMIFS('A.T D67'!O:O,'A.T D67'!$A:$A,$A10) -> 5.2 | O10: =SUMIFS('A.T D0'!P:P,'A.T D0'!$A:$A,$A10)+SUMIFS('A.T D7'!P:P,'A.T D7'!$A:$A,$A10)+SUMIFS('A.T D22'!P:P,'A.T D22'!$A:$A,$A10)+SUMIFS('A.T D37'!P:P,'A.T D37'!$A:$A,$A10)+SUMIFS('A.T D52'!P:P,'A.T D52'!$A:$A,$A10)+SUMIFS('A.T D67'!P:P,'A.T D67'!$A:$A,$A10) -> 17.14 | P10: =SUMIFS('A.T D0'!Q:Q,'A.T D0'!$A:$A,$A10)+SUMIFS('A.T D7'!Q:Q,'A.T D7'!$A:$A,$A10)+SUMIFS('A.T D22'!Q:Q,'A.T D22'!$A:$A,$A10)+SUMIFS('A.T D37'!Q:Q,'A.T D37'!$A:$A,$A10)+SUMIFS('A.T D52'!Q:Q,'A.T D52'!$A:$A,$A10)+SUMIFS('A.T D67'!Q:Q,'A.T D67'!$A:$A,$A10) -> 13.26 | Q10: =SUMIFS('A.T D0'!R:R,'A.T D0'!$A:$A,$A10)+SUMIFS('A.T D7'!R:R,'A.T D7'!$A:$A,$A10)+SUMIFS('A.T D22'!R:R,'A.T D22'!$A:$A,$A10)+SUMIFS('A.T D37'!R:R,'A.T D37'!$A:$A,$A10)+SUMIFS('A.T D52'!R:R,'A.T D52'!$A:$A,$A10)+SUMIFS('A.T D67'!R:R,'A.T D67'!$A:$A,$A10) -> 77.36 | R10: =SUMIFS('A.T D0'!S:S,'A.T D0'!$A:$A,$A10)+SUMIFS('A.T D7'!S:S,'A.T D7'!$A:$A,$A10)+SUMIFS('A.T D22'!S:S,'A.T D22'!$A:$A,$A10)+SUMIFS('A.T D37'!S:S,'A.T D37'!$A:$A,$A10)+SUMIFS('A.T D52'!S:S,'A.T D52'!$A:$A,$A10)+SUMIFS('A.T D67'!S:S,'A.T D67'!$A:$A,$A10) -> 0.99 | S10: =SUMIFS('A.T D0'!T:T,'A.T D0'!$A:$A,$A10)+SUMIFS('A.T D7'!T:T,'A.T D7'!$A:$A,$A10)+SUMIFS('A.T D22'!T:T,'A.T D22'!$A:$A,$A10)+SUMIFS('A.T D37'!T:T,'A.T D37'!$A:$A,$A10)+SUMIFS('A.T D52'!T:T,'A.T D52'!$A:$A,$A10)+SUMIFS('A.T D67'!T:T,'A.T D67'!$A:$A,$A10) -> 11.2075 | T10: =SUMIFS('A.T D0'!U:U,'A.T D0'!$A:$A,$A10)+SUMIFS('A.T D7'!U:U,'A.T D7'!$A:$A,$A10)+SUMIFS('A.T D22'!U:U,'A.T D22'!$A:$A,$A10)+SUMIFS('A.T D37'!U:U,'A.T D37'!$A:$A,$A10)+SUMIFS('A.T D52'!U:U,'A.T D52'!$A:$A,$A10)+SUMIFS('A.T D67'!U:U,'A.T D67'!$A:$A,$A10) -> 0.84 | U10: =SUMIFS('A.T D0'!V:V,'A.T D0'!$A:$A,$A10)+SUMIFS('A.T D7'!V:V,'A.T D7'!$A:$A,$A10)+SUMIFS('A.T D22'!V:V,'A.T D22'!$A:$A,$A10)+SUMIFS('A.T D37'!V:V,'A.T D37'!$A:$A,$A10)+SUMIFS('A.T D52'!V:V,'A.T D52'!$A:$A,$A10)+SUMIFS('A.T D67'!V:V,'A.T D67'!$A:$A,$A10) -> 12.11 | V10: =SUMIFS('A.T D0'!W:W,'A.T D0'!$A:$A,$A10)+SUMIFS('A.T D7'!W:W,'A.T D7'!$A:$A,$A10)+SUMIFS('A.T D22'!W:W,'A.T D22'!$A:$A,$A10)+SUMIFS('A.T D37'!W:W,'A.T D37'!$A:$A,$A10)+SUMIFS('A.T D52'!W:W,'A.T D52'!$A:$A,$A10)+SUMIFS('A.T D67'!W:W,'A.T D67'!$A:$A,$A10) -> -2.49 | W10: =SUMIFS('A.T D0'!X:X,'A.T D0'!$A:$A,$A10)+SUMIFS('A.T D7'!X:X,'A.T D7'!$A:$A,$A10)+SUMIFS('A.T D22'!X:X,'A.T D22'!$A:$A,$A10)+SUMIFS('A.T D37'!X:X,'A.T D37'!$A:$A,$A10)+SUMIFS('A.T D52'!X:X,'A.T D52'!$A:$A,$A10)+SUMIFS('A.T D67'!X:X,'A.T D67'!$A:$A,$A10) -> 115.63 | X10: =SUMIFS(TCH!J:J,TCH!$A:$A,$A10) -> 0 | Y10: =IF(X10=0,0,(X10*AVERAGEIFS($W:$W,$C:$C,$C10,$D:$D,$D10,$E:$E,$E10,$G:$G,$G10,$B:$B,_xlfn.MAXIFS($B:$B,$C:$C,$C10,$D:$D,$D10,$E:$E,$E10,$G:$G,$G10,$B:$B,"<>"&$B10)))/1000) -> 0 | Z10: =SUMIFS(TCH!M:M,TCH!$A:$A,$A10) -> 0 | AA10: =IF(Z10=0,0,(Z10*AVERAGEIFS($W:$W,$C:$C,$C10,$D:$D,$D10,$E:$E,$E10,$G:$G,$G10,$B:$B,_xlfn.MAXIFS($B:$B,$C:$C,$C10,$D:$D,$D10,$E:$E,$E10,$G:$G,$G10,$B:$B,"<>"&$B10)))/1000) -> 0 | AB10: =SUMIFS(TCH!P:P,TCH!$A:$A,$A10) -> 0 | AC10: =IF(AB10=0,0,(AB10*AVERAGEIFS($W:$W,$C:$C,$C10,$D:$D,$D10,$E:$E,$E10,$G:$G,$G10,$B:$B,_xlfn.MAXIFS($B:$B,$C:$C,$C10,$D:$D,$D10,$E:$E,$E10,$G:$G,$G10,$B:$B,"<>"&$B10)))/1000) -> 0 | AD10: =SUMIFS(TCH!S:S,TCH!$A:$A,$A10) -> 0 | AE10: =IF(AD10=0,0,(AD10*AVERAGEIFS($W:$W,$C:$C,$C10,$D:$D,$D10,$E:$E,$E10,$G:$G,$G10,$B:$B,_xlfn.MAXIFS($B:$B,$C:$C,$C10,$D:$D,$D10,$E:$E,$E10,$G:$G,$G10,$B:$B,"<>"&$B10)))/1000) -> 0 | AF10: =SUMIFS(TCH!V:V,TCH!$A:$A,$A10) -> 0 | AG10: =IF(AF10=0,0,(AF10*AVERAGEIFS($W:$W,$C:$C,$C10,$D:$D,$D10,$E:$E,$E10,$G:$G,$G10,$B:$B,_xlfn.MAXIFS($B:$B,$C:$C,$C10,$D:$D,$D10,$E:$E,$E10,$G:$G,$G10,$B:$B,"<>"&$B10)))/1000) -> 0 | AH10: =SUMIFS(TCH!Y:Y,TCH!$A:$A,$A10) -> 0 | AI10: =IF(AH10=0,0,(AH10*AVERAGEIFS($W:$W,$C:$C,$C10,$D:$D,$D10,$E:$E,$E10,$G:$G,$G10,$B:$B,_xlfn.MAXIFS($B:$B,$C:$C,$C10,$D:$D,$D10,$E:$E,$E10,$G:$G,$G10,$B:$B,"<>"&$B10)))/1000) -> 0 | AJ10: 0 | AK10: 0 | AL10: 0 | AM10: 0 | AN10: 0 | AO10: 0 | AP10: 0 | AQ10: 0 | AR10: 0 | AS10: 0 | AT10: 0 | AU10: 0 | AV10: 0 | AW10: 0 | AX10: 0 | AY10: 0 | AZ10: 0
A11: =B11&C11&D11&E11&F11&G11 -> 45733491B4R130 | B11: 45733 | C11: 49 | D11: 1 | E11: B4 | F11: R1 | G11: 30 | H11: =SUMIFS(Biometria!H:H,Biometria!$A:$A,$A11) -> 18 | I11: =SUMIFS(Biometria!I:I,Biometria!$A:$A,$A11) -> 18.056667 | J11: =SUMIFS(Biometria!J:J,Biometria!$A:$A,$A11) -> 0 | K11: =SUMIFS(Biometria!K:K,Biometria!$A:$A,$A11) -> 2.85 | L11: =SUMIFS(Biometria!L:L,Biometria!$A:$A,$A11) -> 0 | M11: =SUMIFS(Biometria!M:M,Biometria!$A:$A,$A11) -> 0 | N11: =SUMIFS('A.T D0'!O:O,'A.T D0'!$A:$A,$A11)+SUMIFS('A.T D7'!O:O,'A.T D7'!$A:$A,$A11)+SUMIFS('A.T D22'!O:O,'A.T D22'!$A:$A,$A11)+SUMIFS('A.T D37'!O:O,'A.T D37'!$A:$A,$A11)+SUMIFS('A.T D52'!O:O,'A.T D52'!$A:$A,$A11)+SUMIFS('A.T D67'!O:O,'A.T D67'!$A:$A,$A11) -> 5.2 | O11: =SUMIFS('A.T D0'!P:P,'A.T D0'!$A:$A,$A11)+SUMIFS('A.T D7'!P:P,'A.T D7'!$A:$A,$A11)+SUMIFS('A.T D22'!P:P,'A.T D22'!$A:$A,$A11)+SUMIFS('A.T D37'!P:P,'A.T D37'!$A:$A,$A11)+SUMIFS('A.T D52'!P:P,'A.T D52'!$A:$A,$A11)+SUMIFS('A.T D67'!P:P,'A.T D67'!$A:$A,$A11) -> 17.11 | P11: =SUMIFS('A.T D0'!Q:Q,'A.T D0'!$A:$A,$A11)+SUMIFS('A.T D7'!Q:Q,'A.T D7'!$A:$A,$A11)+SUMIFS('A.T D22'!Q:Q,'A.T D22'!$A:$A,$A11)+SUMIFS('A.T D37'!Q:Q,'A.T D37'!$A:$A,$A11)+SUMIFS('A.T D52'!Q:Q,'A.T D52'!$A:$A,$A11)+SUMIFS('A.T D67'!Q:Q,'A.T D67'!$A:$A,$A11) -> 13.18 | Q11: =SUMIFS('A.T D0'!R:R,'A.T D0'!$A:$A,$A11)+SUMIFS('A.T D7'!R:R,'A.T D7'!$A:$A,$A11)+SUMIFS('A.T D22'!R:R,'A.T D22'!$A:$A,$A11)+SUMIFS('A.T D37'!R:R,'A.T D37'!$A:$A,$A11)+SUMIFS('A.T D52'!R:R,'A.T D52'!$A:$A,$A11)+SUMIFS('A.T D67'!R:R,'A.T D67'!$A:$A,$A11) -> 77.03 | R11: =SUMIFS('A.T D0'!S:S,'A.T D0'!$A:$A,$A11)+SUMIFS('A.T D7'!S:S,'A.T D7'!$A:$A,$A11)+SUMIFS('A.T D22'!S:S,'A.T D22'!$A:$A,$A11)+SUMIFS('A.T D37'!S:S,'A.T D37'!$A:$A,$A11)+SUMIFS('A.T D52'!S:S,'A.T D52'!$A:$A,$A11)+SUMIFS('A.T D67'!S:S,'A.T D67'!$A:$A,$A11) -> 1 | S11: =SUMIFS('A.T D0'!T:T,'A.T D0'!$A:$A,$A11)+SUMIFS('A.T D7'!T:T,'A.T D7'!$A:$A,$A11)+SUMIFS('A.T D22'!T:T,'A.T D22'!$A:$A,$A11)+SUMIFS('A.T D37'!T:T,'A.T D37'!$A:$A,$A11)+SUMIFS('A.T D52'!T:T,'A.T D52'!$A:$A,$A11)+SUMIFS('A.T D67'!T:T,'A.T D67'!$A:$A,$A11) -> 11.028 | T11: =SUMIFS('A.T D0'!U:U,'A.T D0'!$A:$A,$A11)+SUMIFS('A.T D7'!U:U,'A.T D7'!$A:$A,$A11)+SUMIFS('A.T D22'!U:U,'A.T D22'!$A:$A,$A11)+SUMIFS('A.T D37'!U:U,'A.T D37'!$A:$A,$A11)+SUMIFS('A.T D52'!U:U,'A.T D52'!$A:$A,$A11)+SUMIFS('A.T D67'!U:U,'A.T D67'!$A:$A,$A11) -> 0.84 | U11: =SUMIFS('A.T D0'!V:V,'A.T D0'!$A:$A,$A11)+SUMIFS('A.T D7'!V:V,'A.T D7'!$A:$A,$A11)+SUMIFS('A.T D22'!V:V,'A.T D22'!$A:$A,$A11)+SUMIFS('A.T D37'!V:V,'A.T D37'!$A:$A,$A11)+SUMIFS('A.T D52'!V:V,'A.T D52'!$A:$A,$A11)+SUMIFS('A.T D67'!V:V,'A.T D67'!$A:$A,$A11) -> 12.69 | V11: =SUMIFS('A.T D0'!W:W,'A.T D0'!$A:$A,$A11)+SUMIFS('A.T D7'!W:W,'A.T D7'!$A:$A,$A11)+SUMIFS('A.T D22'!W:W,'A.T D22'!$A:$A,$A11)+SUMIFS('A.T D37'!W:W,'A.T D37'!$A:$A,$A11)+SUMIFS('A.T D52'!W:W,'A.T D52'!$A:$A,$A11)+SUMIFS('A.T D67'!W:W,'A.T D67'!$A:$A,$A11) -> -3.95 | W11: =SUMIFS('A.T D0'!X:X,'A.T D0'!$A:$A,$A11)+SUMIFS('A.T D7'!X:X,'A.T D7'!$A:$A,$A11)+SUMIFS('A.T D22'!X:X,'A.T D22'!$A:$A,$A11)+SUMIFS('A.T D37'!X:X,'A.T D37'!$A:$A,$A11)+SUMIFS('A.T D52'!X:X,'A.T D52'!$A:$A,$A11)+SUMIFS('A.T D67'!X:X,'A.T D67'!$A:$A,$A11) -> 113.9 | X11: =SUMIFS(TCH!J:J,TCH!$A:$A,$A11) -> 0 | Y11: =IF(X11=0,0,(X11*AVERAGEIFS($W:$W,$C:$C,$C11,$D:$D,$D11,$E:$E,$E11,$G:$G,$G11,$B:$B,_xlfn.MAXIFS($B:$B,$C:$C,$C11,$D:$D,$D11,$E:$E,$E11,$G:$G,$G11,$B:$B,"<>"&$B11)))/1000) -> 0 | Z11: =SUMIFS(TCH!M:M,TCH!$A:$A,$A11) -> 0 | AA11: =IF(Z11=0,0,(Z11*AVERAGEIFS($W:$W,$C:$C,$C11,$D:$D,$D11,$E:$E,$E11,$G:$G,$G11,$B:$B,_xlfn.MAXIFS($B:$B,$C:$C,$C11,$D:$D,$D11,$E:$E,$E11,$G:$G,$G11,$B:$B,"<>"&$B11)))/1000) -> 0 | AB11: =SUMIFS(TCH!P:P,TCH!$A:$A,$A11) -> 0 | AC11: =IF(AB11=0,0,(AB11*AVERAGEIFS($W:$W,$C:$C,$C11,$D:$D,$D11,$E:$E,$E11,$G:$G,$G11,$B:$B,_xlfn.MAXIFS($B:$B,$C:$C,$C11,$D:$D,$D11,$E:$E,$E11,$G:$G,$G11,$B:$B,"<>"&$B11)))/1000) -> 0 | AD11: =SUMIFS(TCH!S:S,TCH!$A:$A,$A11) -> 0 | AE11: =IF(AD11=0,0,(AD11*AVERAGEIFS($W:$W,$C:$C,$C11,$D:$D,$D11,$E:$E,$E11,$G:$G,$G11,$B:$B,_xlfn.MAXIFS($B:$B,$C:$C,$C11,$D:$D,$D11,$E:$E,$E11,$G:$G,$G11,$B:$B,"<>"&$B11)))/1000) -> 0 | AF11: =SUMIFS(TCH!V:V,TCH!$A:$A,$A11) -> 0 | AG11: =IF(AF11=0,0,(AF11*AVERAGEIFS($W:$W,$C:$C,$C11,$D:$D,$D11,$E:$E,$E11,$G:$G,$G11,$B:$B,_xlfn.MAXIFS($B:$B,$C:$C,$C11,$D:$D,$D11,$E:$E,$E11,$G:$G,$G11,$B:$B,"<>"&$B11)))/1000) -> 0 | AH11: =SUMIFS(TCH!Y:Y,TCH!$A:$A,$A11) -> 0 | AI11: =IF(AH11=0,0,(AH11*AVERAGEIFS($W:$W,$C:$C,$C11,$D:$D,$D11,$E:$E,$E11,$G:$G,$G11,$B:$B,_xlfn.MAXIFS($B:$B,$C:$C,$C11,$D:$D,$D11,$E:$E,$E11,$G:$G,$G11,$B:$B,"<>"&$B11)))/1000) -> 0 | AJ11: 0 | AK11: 0 | AL11: 0 | AM11: 0 | AN11: 0 | AO11: 0 | AP11: 0 | AQ11: 0 | AR11: 0 | AS11: 0 | AT11: 0 | AU11: 0 | AV11: 0 | AW11: 0 | AX11: 0 | AY11: 0 | AZ11: 0
A12: =B12&C12&D12&E12&F12&G12 -> 45733491B4R230 | B12: 45733 | C12: 49 | D12: 1 | E12: B4 | F12: R2 | G12: 30 | H12: =SUMIFS(Biometria!H:H,Biometria!$A:$A,$A12) -> 18.16 | I12: =SUMIFS(Biometria!I:I,Biometria!$A:$A,$A12) -> 0 | J12: =SUMIFS(Biometria!J:J,Biometria!$A:$A,$A12) -> 0 | K12: =SUMIFS(Biometria!K:K,Biometria!$A:$A,$A12) -> 0 | L12: =SUMIFS(Biometria!L:L,Biometria!$A:$A,$A12) -> 0 | M12: =SUMIFS(Biometria!M:M,Biometria!$A:$A,$A12) -> 0 | N12: =SUMIFS('A.T D0'!O:O,'A.T D0'!$A:$A,$A12)+SUMIFS('A.T D7'!O:O,'A.T D7'!$A:$A,$A12)+SUMIFS('A.T D22'!O:O,'A.T D22'!$A:$A,$A12)+SUMIFS('A.T D37'!O:O,'A.T D37'!$A:$A,$A12)+SUMIFS('A.T D52'!O:O,'A.T D52'!$A:$A,$A12)+SUMIFS('A.T D67'!O:O,'A.T D67'!$A:$A,$A12) -> 5.2 | O12: =SUMIFS('A.T D0'!P:P,'A.T D0'!$A:$A,$A12)+SUMIFS('A.T D7'!P:P,'A.T D7'!$A:$A,$A12)+SUMIFS('A.T D22'!P:P,'A.T D22'!$A:$A,$A12)+SUMIFS('A.T D37'!P:P,'A.T D37'!$A:$A,$A12)+SUMIFS('A.T D52'!P:P,'A.T D52'!$A:$A,$A12)+SUMIFS('A.T D67'!P:P,'A.T D67'!$A:$A,$A12) -> 17.16 | P12: =SUMIFS('A.T D0'!Q:Q,'A.T D0'!$A:$A,$A12)+SUMIFS('A.T D7'!Q:Q,'A.T D7'!$A:$A,$A12)+SUMIFS('A.T D22'!Q:Q,'A.T D22'!$A:$A,$A12)+SUMIFS('A.T D37'!Q:Q,'A.T D37'!$A:$A,$A12)+SUMIFS('A.T D52'!Q:Q,'A.T D52'!$A:$A,$A12)+SUMIFS('A.T D67'!Q:Q,'A.T D67'!$A:$A,$A12) -> 13.08 | Q12: =SUMIFS('A.T D0'!R:R,'A.T D0'!$A:$A,$A12)+SUMIFS('A.T D7'!R:R,'A.T D7'!$A:$A,$A12)+SUMIFS('A.T D22'!R:R,'A.T D22'!$A:$A,$A12)+SUMIFS('A.T D37'!R:R,'A.T D37'!$A:$A,$A12)+SUMIFS('A.T D52'!R:R,'A.T D52'!$A:$A,$A12)+SUMIFS('A.T D67'!R:R,'A.T D67'!$A:$A,$A12) -> 76.22 | R12: =SUMIFS('A.T D0'!S:S,'A.T D0'!$A:$A,$A12)+SUMIFS('A.T D7'!S:S,'A.T D7'!$A:$A,$A12)+SUMIFS('A.T D22'!S:S,'A.T D22'!$A:$A,$A12)+SUMIFS('A.T D37'!S:S,'A.T D37'!$A:$A,$A12)+SUMIFS('A.T D52'!S:S,'A.T D52'!$A:$A,$A12)+SUMIFS('A.T D67'!S:S,'A.T D67'!$A:$A,$A12) -> 1.03 | S12: =SUMIFS('A.T D0'!T:T,'A.T D0'!$A:$A,$A12)+SUMIFS('A.T D7'!T:T,'A.T D7'!$A:$A,$A12)+SUMIFS('A.T D22'!T:T,'A.T D22'!$A:$A,$A12)+SUMIFS('A.T D37'!T:T,'A.T D37'!$A:$A,$A12)+SUMIFS('A.T D52'!T:T,'A.T D52'!$A:$A,$A12)+SUMIFS('A.T D67'!T:T,'A.T D67'!$A:$A,$A12) -> 10.929 | T12: =SUMIFS('A.T D0'!U:U,'A.T D0'!$A:$A,$A12)+SUMIFS('A.T D7'!U:U,'A.T D7'!$A:$A,$A12)+SUMIFS('A.T D22'!U:U,'A.T D22'!$A:$A,$A12)+SUMIFS('A.T D37'!U:U,'A.T D37'!$A:$A,$A12)+SUMIFS('A.T D52'!U:U,'A.T D52'!$A:$A,$A12)+SUMIFS('A.T D67'!U:U,'A.T D67'!$A:$A,$A12) -> 0.86 | U12: =SUMIFS('A.T D0'!V:V,'A.T D0'!$A:$A,$A12)+SUMIFS('A.T D7'!V:V,'A.T D7'!$A:$A,$A12)+SUMIFS('A.T D22'!V:V,'A.T D22'!$A:$A,$A12)+SUMIFS('A.T D37'!V:V,'A.T D37'!$A:$A,$A12)+SUMIFS('A.T D52'!V:V,'A.T D52'!$A:$A,$A12)+SUMIFS('A.T D67'!V:V,'A.T D67'!$A:$A,$A12) -> 12.77 | V12: =SUMIFS('A.T D0'!W:W,'A.T D0'!$A:$A,$A12)+SUMIFS('A.T D7'!W:W,'A.T D7'!$A:$A,$A12)+SUMIFS('A.T D22'!W:W,'A.T D22'!$A:$A,$A12)+SUMIFS('A.T D37'!W:W,'A.T D37'!$A:$A,$A12)+SUMIFS('A.T D52'!W:W,'A.T D52'!$A:$A,$A12)+SUMIFS('A.T D67'!W:W,'A.T D67'!$A:$A,$A12) -> -4.6 | W12: =SUMIFS('A.T D0'!X:X,'A.T D0'!$A:$A,$A12)+SUMIFS('A.T D7'!X:X,'A.T D7'!$A:$A,$A12)+SUMIFS('A.T D22'!X:X,'A.T D22'!$A:$A,$A12)+SUMIFS('A.T D37'!X:X,'A.T D37'!$A:$A,$A12)+SUMIFS('A.T D52'!X:X,'A.T D52'!$A:$A,$A12)+SUMIFS('A.T D67'!X:X,'A.T D67'!$A:$A,$A12) -> 113.13 | X12: =SUMIFS(TCH!J:J,TCH!$A:$A,$A12) -> 0 | Y12: =IF(X12=0,0,(X12*AVERAGEIFS($W:$W,$C:$C,$C12,$D:$D,$D12,$E:$E,$E12,$G:$G,$G12,$B:$B,_xlfn.MAXIFS($B:$B,$C:$C,$C12,$D:$D,$D12,$E:$E,$E12,$G:$G,$G12,$B:$B,"<>"&$B12)))/1000) -> 0 | Z12: =SUMIFS(TCH!M:M,TCH!$A:$A,$A12) -> 0 | AA12: =IF(Z12=0,0,(Z12*AVERAGEIFS($W:$W,$C:$C,$C12,$D:$D,$D12,$E:$E,$E12,$G:$G,$G12,$B:$B,_xlfn.MAXIFS($B:$B,$C:$C,$C12,$D:$D,$D12,$E:$E,$E12,$G:$G,$G12,$B:$B,"<>"&$B12)))/1000) -> 0 | AB12: =SUMIFS(TCH!P:P,TCH!$A:$A,$A12) -> 0 | AC12: =IF(AB12=0,0,(AB12*AVERAGEIFS($W:$W,$C:$C,$C12,$D:$D,$D12,$E:$E,$E12,$G:$G,$G12,$B:$B,_xlfn.MAXIFS($B:$B,$C:$C,$C12,$D:$D,$D12,$E:$E,$E12,$G:$G,$G12,$B:$B,"<>"&$B12)))/1000) -> 0 | AD12: =SUMIFS(TCH!S:S,TCH!$A:$A,$A12) -> 0 | AE12: =IF(AD12=0,0,(AD12*AVERAGEIFS($W:$W,$C:$C,$C12,$D:$D,$D12,$E:$E,$E12,$G:$G,$G12,$B:$B,_xlfn.MAXIFS($B:$B,$C:$C,$C12,$D:$D,$D12,$E:$E,$E12,$G:$G,$G12,$B:$B,"<>"&$B12)))/1000) -> 0 | AF12: =SUMIFS(TCH!V:V,TCH!$A:$A,$A12) -> 0 | AG12: =IF(AF12=0,0,(AF12*AVERAGEIFS($W:$W,$C:$C,$C12,$D:$D,$D12,$E:$E,$E12,$G:$G,$G12,$B:$B,_xlfn.MAXIFS($B:$B,$C:$C,$C12,$D:$D,$D12,$E:$E,$E12,$G:$G,$G12,$B:$B,"<>"&$B12)))/1000) -> 0 | AH12: =SUMIFS(TCH!Y:Y,TCH!$A:$A,$A12) -> 0 | AI12: =IF(AH12=0,0,(AH12*AVERAGEIFS($W:$W,$C:$C,$C12,$D:$D,$D12,$E:$E,$E12,$G:$G,$G12,$B:$B,_xlfn.MAXIFS($B:$B,$C:$C,$C12,$D:$D,$D12,$E:$E,$E12,$G:$G,$G12,$B:$B,"<>"&$B12)))/1000) -> 0 | AJ12: 0 | AK12: 0 | AL12: 0 | AM12: 0 | AN12: 0 | AO12: 0 | AP12: 0 | AQ12: 0 | AR12: 0 | AS12: 0 | AT12: 0 | AU12: 0 | AV12: 0 | AW12: 0 | AX12: 0 | AY12: 0 | AZ12: 0
A13: =B13&C13&D13&E13&F13&G13 -> 45733491B4R330 | B13: 45733 | C13: 49 | D13: 1 | E13: B4 | F13: R3 | G13: 30 | H13: =SUMIFS(Biometria!H:H,Biometria!$A:$A,$A13) -> 18.01 | I13: =SUMIFS(Biometria!I:I,Biometria!$A:$A,$A13) -> 0 | J13: =SUMIFS(Biometria!J:J,Biometria!$A:$A,$A13) -> 0 | K13: =SUMIFS(Biometria!K:K,Biometria!$A:$A,$A13) -> 0 | L13: =SUMIFS(Biometria!L:L,Biometria!$A:$A,$A13) -> 0 | M13: =SUMIFS(Biometria!M:M,Biometria!$A:$A,$A13) -> 0 | N13: =SUMIFS('A.T D0'!O:O,'A.T D0'!$A:$A,$A13)+SUMIFS('A.T D7'!O:O,'A.T D7'!$A:$A,$A13)+SUMIFS('A.T D22'!O:O,'A.T D22'!$A:$A,$A13)+SUMIFS('A.T D37'!O:O,'A.T D37'!$A:$A,$A13)+SUMIFS('A.T D52'!O:O,'A.T D52'!$A:$A,$A13)+SUMIFS('A.T D67'!O:O,'A.T D67'!$A:$A,$A13) -> 5.2 | O13: =SUMIFS('A.T D0'!P:P,'A.T D0'!$A:$A,$A13)+SUMIFS('A.T D7'!P:P,'A.T D7'!$A:$A,$A13)+SUMIFS('A.T D22'!P:P,'A.T D22'!$A:$A,$A13)+SUMIFS('A.T D37'!P:P,'A.T D37'!$A:$A,$A13)+SUMIFS('A.T D52'!P:P,'A.T D52'!$A:$A,$A13)+SUMIFS('A.T D67'!P:P,'A.T D67'!$A:$A,$A13) -> 17.15 | P13: =SUMIFS('A.T D0'!Q:Q,'A.T D0'!$A:$A,$A13)+SUMIFS('A.T D7'!Q:Q,'A.T D7'!$A:$A,$A13)+SUMIFS('A.T D22'!Q:Q,'A.T D22'!$A:$A,$A13)+SUMIFS('A.T D37'!Q:Q,'A.T D37'!$A:$A,$A13)+SUMIFS('A.T D52'!Q:Q,'A.T D52'!$A:$A,$A13)+SUMIFS('A.T D67'!Q:Q,'A.T D67'!$A:$A,$A13) -> 13.32 | Q13: =SUMIFS('A.T D0'!R:R,'A.T D0'!$A:$A,$A13)+SUMIFS('A.T D7'!R:R,'A.T D7'!$A:$A,$A13)+SUMIFS('A.T D22'!R:R,'A.T D22'!$A:$A,$A13)+SUMIFS('A.T D37'!R:R,'A.T D37'!$A:$A,$A13)+SUMIFS('A.T D52'!R:R,'A.T D52'!$A:$A,$A13)+SUMIFS('A.T D67'!R:R,'A.T D67'!$A:$A,$A13) -> 77.67 | R13: =SUMIFS('A.T D0'!S:S,'A.T D0'!$A:$A,$A13)+SUMIFS('A.T D7'!S:S,'A.T D7'!$A:$A,$A13)+SUMIFS('A.T D22'!S:S,'A.T D22'!$A:$A,$A13)+SUMIFS('A.T D37'!S:S,'A.T D37'!$A:$A,$A13)+SUMIFS('A.T D52'!S:S,'A.T D52'!$A:$A,$A13)+SUMIFS('A.T D67'!S:S,'A.T D67'!$A:$A,$A13) -> 0.98 | S13: =SUMIFS('A.T D0'!T:T,'A.T D0'!$A:$A,$A13)+SUMIFS('A.T D7'!T:T,'A.T D7'!$A:$A,$A13)+SUMIFS('A.T D22'!T:T,'A.T D22'!$A:$A,$A13)+SUMIFS('A.T D37'!T:T,'A.T D37'!$A:$A,$A13)+SUMIFS('A.T D52'!T:T,'A.T D52'!$A:$A,$A13)+SUMIFS('A.T D67'!T:T,'A.T D67'!$A:$A,$A13) -> 11.1315 | T13: =SUMIFS('A.T D0'!U:U,'A.T D0'!$A:$A,$A13)+SUMIFS('A.T D7'!U:U,'A.T D7'!$A:$A,$A13)+SUMIFS('A.T D22'!U:U,'A.T D22'!$A:$A,$A13)+SUMIFS('A.T D37'!U:U,'A.T D37'!$A:$A,$A13)+SUMIFS('A.T D52'!U:U,'A.T D52'!$A:$A,$A13)+SUMIFS('A.T D67'!U:U,'A.T D67'!$A:$A,$A13) -> 0.82 | U13: =SUMIFS('A.T D0'!V:V,'A.T D0'!$A:$A,$A13)+SUMIFS('A.T D7'!V:V,'A.T D7'!$A:$A,$A13)+SUMIFS('A.T D22'!V:V,'A.T D22'!$A:$A,$A13)+SUMIFS('A.T D37'!V:V,'A.T D37'!$A:$A,$A13)+SUMIFS('A.T D52'!V:V,'A.T D52'!$A:$A,$A13)+SUMIFS('A.T D67'!V:V,'A.T D67'!$A:$A,$A13) -> 12.76 | V13: =SUMIFS('A.T D0'!W:W,'A.T D0'!$A:$A,$A13)+SUMIFS('A.T D7'!W:W,'A.T D7'!$A:$A,$A13)+SUMIFS('A.T D22'!W:W,'A.T D22'!$A:$A,$A13)+SUMIFS('A.T D37'!W:W,'A.T D37'!$A:$A,$A13)+SUMIFS('A.T D52'!W:W,'A.T D52'!$A:$A,$A13)+SUMIFS('A.T D67'!W:W,'A.T D67'!$A:$A,$A13) -> -3.26 | W13: =SUMIFS('A.T D0'!X:X,'A.T D0'!$A:$A,$A13)+SUMIFS('A.T D7'!X:X,'A.T D7'!$A:$A,$A13)+SUMIFS('A.T D22'!X:X,'A.T D22'!$A:$A,$A13)+SUMIFS('A.T D37'!X:X,'A.T D37'!$A:$A,$A13)+SUMIFS('A.T D52'!X:X,'A.T D52'!$A:$A,$A13)+SUMIFS('A.T D67'!X:X,'A.T D67'!$A:$A,$A13) -> 114.72 | X13: =SUMIFS(TCH!J:J,TCH!$A:$A,$A13) -> 0 | Y13: =IF(X13=0,0,(X13*AVERAGEIFS($W:$W,$C:$C,$C13,$D:$D,$D13,$E:$E,$E13,$G:$G,$G13,$B:$B,_xlfn.MAXIFS($B:$B,$C:$C,$C13,$D:$D,$D13,$E:$E,$E13,$G:$G,$G13,$B:$B,"<>"&$B13)))/1000) -> 0 | Z13: =SUMIFS(TCH!M:M,TCH!$A:$A,$A13) -> 0 | AA13: =IF(Z13=0,0,(Z13*AVERAGEIFS($W:$W,$C:$C,$C13,$D:$D,$D13,$E:$E,$E13,$G:$G,$G13,$B:$B,_xlfn.MAXIFS($B:$B,$C:$C,$C13,$D:$D,$D13,$E:$E,$E13,$G:$G,$G13,$B:$B,"<>"&$B13)))/1000) -> 0 | AB13: =SUMIFS(TCH!P:P,TCH!$A:$A,$A13) -> 0 | AC13: =IF(AB13=0,0,(AB13*AVERAGEIFS($W:$W,$C:$C,$C13,$D:$D,$D13,$E:$E,$E13,$G:$G,$G13,$B:$B,_xlfn.MAXIFS($B:$B,$C:$C,$C13,$D:$D,$D13,$E:$E,$E13,$G:$G,$G13,$B:$B,"<>"&$B13)))/1000) -> 0 | AD13: =SUMIFS(TCH!S:S,TCH!$A:$A,$A13) -> 0 | AE13: =IF(AD13=0,0,(AD13*AVERAGEIFS($W:$W,$C:$C,$C13,$D:$D,$D13,$E:$E,$E13,$G:$G,$G13,$B:$B,_xlfn.MAXIFS($B:$B,$C:$C,$C13,$D:$D,$D13,$E:$E,$E13,$G:$G,$G13,$B:$B,"<>"&$B13)))/1000) -> 0 | AF13: =SUMIFS(TCH!V:V,TCH!$A:$A,$A13) -> 0 | AG13: =IF(AF13=0,0,(AF13*AVERAGEIFS($W:$W,$C:$C,$C13,$D:$D,$D13,$E:$E,$E13,$G:$G,$G13,$B:$B,_xlfn.MAXIFS($B:$B,$C:$C,$C13,$D:$D,$D13,$E:$E,$E13,$G:$G,$G13,$B:$B,"<>"&$B13)))/1000) -> 0 | AH13: =SUMIFS(TCH!Y:Y,TCH!$A:$A,$A13) -> 0 | AI13: =IF(AH13=0,0,(AH13*AVERAGEIFS($W:$W,$C:$C,$C13,$D:$D,$D13,$E:$E,$E13,$G:$G,$G13,$B:$B,_xlfn.MAXIFS($B:$B,$C:$C,$C13,$D:$D,$D13,$E:$E,$E13,$G:$G,$G13,$B:$B,"<>"&$B13)))/1000) -> 0 | AJ13: 0 | AK13: 0 | AL13: 0 | AM13: 0 | AN13: 0 | AO13: 0 | AP13: 0 | AQ13: 0 | AR13: 0 | AS13: 0 | AT13: 0 | AU13: 0 | AV13: 0 | AW13: 0 | AX13: 0 | AY13: 0 | AZ13: 0
